Workbook

Sheet CONF 
D2: 2
A3: Titular da Reserva:
A4: Data | B4: Passeio | C4: Valor em Pesos Colombianos P/P | D4: Valor Total em Pesos Colombianos TOTAL
A5: 45781 | B5: Aluguel De Moto Elétrica 2 Pessoas | C5: =VLOOKUP(B5,'TARIFAS '!$A$3:$N$239,2,FALSE) -> 180000 | D5: =+C5*$D$2 -> 360000
A6: 45782 | B6: City Tour Panoramico + Catedral de Sal Regular | C6: =VLOOKUP(B6,'TARIFAS '!$A$3:$N$239,2,FALSE) -> 350000 | D6: =+C6*$D$2 -> 700000
A7: 45784 | B7: Bora Bora Bc | C7: =VLOOKUP(B7,'TARIFAS '!$A$3:$N$239,2,FALSE) -> 390000 | D7: =+C7*$D$2 -> 780000
A8: 45785 | B8: Walking Tour + Castillo San Felipe 09:00 1PAX | C8: =VLOOKUP(B8,'TARIFAS '!$A$3:$N$239,2,FALSE) -> 500000 | D8: =+C8*$D$2 -> 1000000
A9: 45786 | B9: Isla Palma | C9: =VLOOKUP(B9,'TARIFAS '!$A$3:$N$239,2,FALSE) -> 530000 | D9: =+C9*$D$2 -> 1060000
A10: 45611 | B10: PAU´E | C10: =VLOOKUP(B10,'TARIFAS '!$A$3:$N$239,2,FALSE) -> 450000 | D10: =+C10*$D$2 -> 900000
A11: 45612 | B11: Bonavida | C11: =VLOOKUP(B11,'TARIFAS '!$A$3:$N$239,2,FALSE) -> 440000 | D11: =+C11*$D$2 -> 880000
A12: 45613 | B12: Bora Bora Vip | C12: =VLOOKUP(B12,'TARIFAS '!$A$3:$N$239,2,FALSE) -> 490000 | D12: =+C12*$D$2 -> 980000
A13: 45614 | B13: Tour en lancha privativa JOE 2024 | C13: =VLOOKUP(B13,'TARIFAS '!$A$3:$N$239,2,FALSE) -> 3700000 | D13: =+C13*$D$2 -> 7400000
A14: 45615 | B14: City Tour + Catedral de Sal Privativo | C14: =VLOOKUP(B14,'TARIFAS '!$A$3:$N$239,2,FALSE) -> 1700000 | D14: =+C14*$D$2 -> 3400000
A15: 45616 | B15: Aluguel De Moto Elétrica 2 Pessoas | C15: =VLOOKUP(B15,'TARIFAS '!$A$3:$N$239,2,FALSE) -> 180000 | D15: =+C15*$D$2 -> 360000
A16: 45617 | B16: City Tour + Catedral de Sal Privativo | C16: =VLOOKUP(B16,'TARIFAS '!$A$3:$N$239,2,FALSE) -> 1700000 | D16: =+C16*$D$2 -> 3400000
... A20: 45621 | B20: PAU´E | C20: =VLOOKUP(B20,'TARIFAS '!$A$3:$N$239,2,FALSE) -> 450000 | D20: =+C20*$D$2 -> 900000
B21: PAU´E | C21: =VLOOKUP(B21,'TARIFAS '!$A$3:$N$239,2,FALSE) -> 450000 | D21: =+C21*$D$2 -> 900000
A22: Valor Total | D22: =SUM(D5:D21) -> 41220000
A23: Desconto | D23: 0 | E23: (*)
A24: Valor Total com Desconto | D24: =+D22-D23 -> 41220000 | E24: (*)
A25: Valor da Entrada | D25: =SUM(Datos!C4:C20)-D23 -> 13880000 | E25: (*)
A26: Valor Saldo | D26: =SUM(Datos!E4:E20) -> 21340000 | E26: (**)
A28: =+D2 -> 2 | C28: =+D25 -> 13880000
A30: ENTRADA : | B30: =+D25 -> 13880000 | C30: no cambio dia | D30: 2222.455
C31: =+TODAY() -> 46067
A32: Dados para depósito Juliana Rotta 3 / Banco Inter Pix CNPJ: 14.909.728.0001/45 Pagamento da entrada e envio do comprovante.
A37: OBS:
A43: Data | B43: Passeio | D43: Valor Saldo
D44: =D2 -> 2
A45: =+A5 -> 45781 | B45: =+B5 -> Aluguel De Moto Elétrica 2 Pessoas | D45: =+Datos!E4 -> 160000
A46: =+A6 -> 45782 | B46: =+B6 -> City Tour Panoramico + Catedral de Sal Regular | D46: =+Datos!E5 -> 0
A47: =+A7 -> 45784 | B47: =+B7 -> Bora Bora Bc | D47: =+Datos!E6 -> 560000
A48: =+A8 -> 45785 | B48: =+B8 -> Walking Tour + Castillo San Felipe 09:00 1PAX | D48: =+Datos!E7 -> 1000000
A49: =+A9 -> 45786 | B49: =+B9 -> Isla Palma | D49: =+Datos!E8 -> 700000
A50: =+A10 -> 45611 | B50: =+B10 -> PAU´E | D50: =+Datos!E9 -> 700000
A51: =+A11 -> 45612 | B51: =+B11 -> Bonavida | D51: =+Datos!E10 -> 740000
A52: =+A12 -> 45613 | B52: =+B12 -> Bora Bora Vip | D52: =+Datos!E11 -> 740000
A53: =+A13 -> 45614 | B53: =+B13 -> Tour en lancha privativa JOE 2024 | D53: =+Datos!E12 -> 2700000
A54: =+A14 -> 45615 | B54: =+B14 -> City Tour + Catedral de Sal Privativo | D54: =+Datos!E13 -> 2360000
A55: =+A15 -> 45616 | B55: =+B15 -> Aluguel De Moto Elétrica 2 Pessoas | D55: =+Datos!E14 -> 160000
...

Sheet Voucher
B5: Voucher The Experience Travel
B9: Titular da Reserva: | D9: ='CONF '!$B$3 -> 0
B11: =+'CONF '!$D$2 -> 2
B13: Data: | C13: =+'CONF '!A5 -> 45781 | F13: Hora: | G13: =+VLOOKUP(C15,'TARIFAS '!$A$3:$O$239,10,FALSE) -> 0
B15: Tour: | C15: =+'CONF '!B5 -> Aluguel De Moto Elétrica 2 Pessoas | I15: Valor a pagar: | J15: =+'CONF '!D45 -> 160000
B17: Local: | C17: =+VLOOKUP(C15,'TARIFAS '!$A$3:$N$239,7,FALSE) -> Apresentar-se na Cidade Amuralhada, Calle 2a de Badillo 36 – 54 - 58 P 1 emabixo do hostal Badillo Diagonal ao Restaurante La Vitrola | I17: =+VLOOKUP(C15,'TARIFAS '!$A$3:$O$239,8,FALSE)*B11 -> 0
I18: =+VLOOKUP(C15,'TARIFAS '!$A$3:$O$239,9,FALSE) -> 0
B24: (+55) 11 981758504
B30: Voucher The Experience Travel
B34: Titular da Reserva: | D34: ='CONF '!$B$3 -> 0
B36: =+'CONF '!$D$2 -> 2
B38: Data: | C38: =+'CONF '!A6 -> 45782 | F38: Hora: | G38: =+VLOOKUP(C40,'TARIFAS '!$A$3:$O$239,10,FALSE) -> 08:55
B40: Tour: | C40: =+'CONF '!B6 -> City Tour Panoramico + Catedral de Sal Regular | I40: Valor a pagar: | J40: =+'CONF '!D46 -> 0
B42: Local: | C42: =+VLOOKUP(C40,'TARIFAS '!$A$3:$N$239,7,FALSE) -> Apresentar-se na Carrera 11A # 93A - 10 em frente do Cafe Juan Valdez | I42: =+VLOOKUP(C40,'TARIFAS '!$A$3:$O$239,8,FALSE)*B36 -> 0
I43: =+VLOOKUP(C40,'TARIFAS '!$A$3:$O$239,9,FALSE) -> 0
B49: (+55) 11 981758504
B55: Voucher The Experience Travel
B59: Titular da Reserva: | D59: ='CONF '!$B$3 -> 0
B61: =+'CONF '!$D$2 -> 2
B63: Data: | C63: =+'CONF '!A7 -> 45784 | F63: Hora: | G63: =+VLOOKUP(C65,'TARIFAS '!$A$3:$O$239,10,FALSE) -> 07:20
B65: Tour: | C65: =+'CONF '!B7 -> Bora Bora Bc | I65: Valor a pagar: | J65: =+'CONF '!D47 -> 560000
B67: Local: | C67: =+VLOOKUP(C65,'TARIFAS '!$A$3:$N$239,7,FALSE) -> Apresentar-se na porta 03 da Marina la Bodeguita. | I67: =+VLOOKUP(C65,'TARIFAS '!$A$3:$O$239,8,FALSE)*B61 -> 68000
I68: =+VLOOKUP(C65,'TARIFAS '!$A$3:$O$239,9,FALSE) -> Pagar a taxas portuárias COP 29.000 + Seguro COP 5.000 (valor por pessoa – somente em dinheiro. Valor sujeito a alterações)
B74: (+55) 11 981758504
B80: Voucher The Experience Travel
B84: Titular da Reserva: | D84: ='CONF '!$B$3 -> 0
B86: =+'CONF '!$D$2 -> 2
B88: Data: | C88: =+'CONF '!A8 -> 45785 | F88: Hora: | G88: =+VLOOKUP(C90,'TARIFAS '!$A$3:$O$239,10,FALSE) -> 09:00
B90: Tour: | C90: =+'CONF '!B8 -> Walking Tour + Castillo San Felipe 09:00 1PAX | I90: Valor a pagar: | J90: =+'CONF '!D48 -> 1000000
B92: Local: | C92: =+VLOOKUP(C90,'TARIFAS '!$A$3:$N$239,7,FALSE) -> Apresentar-se na recepção do hotel | I92: =+VLOOKUP(C90,'TARIFAS '!$A$3:$O$239,8,FALSE)*B86 -> 0
I93: =+VLOOKUP(C90,'TARIFAS '!$A$3:$O$239,9,FALSE) -> 0
B99: (+55) 11 981758504
B105: Voucher The Experience Travel
B109: Titular da Reserva: | D109: ='CONF '!$B$3 -> 0
B111: =+'CONF '!$D$2 -> 2
B113: Data: | C113: =+'CONF '!A9 -> 45786 | F113: Hora: | G113: =+VLOOKUP(C115,'TARIFAS '!$A$3:$O$239,10,FALSE) -> 05:45
B115: Tour: | C115: =+'CONF '!B9 -> Isla Palma | I115: Valor a pagar: | J115: =+'CONF '!D49 -> 700000
B117: Local: | C117: =+VLOOKUP(C115,'TARIFAS '!$A$3:$N$239,7,FALSE) -> Apresentar-se na porta 02 da Marina la Bodeguita, onde a pessoa responsável pelo embarque e dará o suporte no embarque. | I117: =+VLOOKUP(C115,'TARIFAS '!$A$3:$O$239,8,FALSE)*B111 -> 58000
I118: =+VLOOKUP(C115,'TARIFAS '!$A$3:$O$239,9,FALSE) -> Pagar a taxas portuárias COP 29.000 (valor por pessoa– somente em dinheiro) na van para entrar na Marina.
B124: (+55) 11 981758504
...

Sheet Voucher OLD
B5: Voucher The Experience Travel
B9: Titular da Reserva: | D9: Luis Domingo Blasini
B11: =+'CONF '!D2 -> 2
B13: Data: | C13: =+'CONF '!A5 -> 45781 | F13: Hora: | G13: 0.61458333
B15: Tour: | C15: =+'CONF '!B5 -> Aluguel De Moto Elétrica 2 Pessoas | I15: Valor a pagar: | J15: =+'CONF '!D45 -> 160000
B17: Local: | C17: =+VLOOKUP(O8,'TARIFAS '!$A$3:$N$239,7,FALSE) -> #N/A | I17: Valor taxas:
B22: (55) 11 981758504
F24: Data: | G24: =+'CONF '!A6 -> 45782
F26: Tour: | G26: =+'CONF '!B6 -> City Tour Panoramico + Catedral de Sal Regular
F28: Embarque: | G28: =+VLOOKUP(G26,'TARIFAS '!$A$3:$N$239,7,FALSE) -> Apresentar-se na Carrera 11A # 93A - 10 em frente do Cafe Juan Valdez
F32: Titular da Reserva: | G32: =+'CONF '!$B$3 -> 0
F33: Nº de pessoas: | G33: =+'CONF '!$D$2 -> 2
F35: Valor a pagar no passeio: | H35: =+'CONF '!D46 -> 0
F36: Valor taxas a pagar no passeio: | H36: =+VLOOKUP(G26,'TARIFAS '!$A$3:$O$239,8,FALSE)*G33 -> 0
F43: Data: | G43: =+'CONF '!A7 -> 45784
F45: Tour: | G45: =+'CONF '!B7 -> Bora Bora Bc
F47: Embarque: | G47: =+VLOOKUP(G45,'TARIFAS '!$A$3:$N$239,7,FALSE) -> Apresentar-se na porta 03 da Marina la Bodeguita.
F51: Titular da Reserva: | G51: =+'CONF '!$B$3 -> 0
F52: Nº de pessoas: | G52: =+'CONF '!$D$2 -> 2
F54: Valor a pagar no passeio: | H54: =+'CONF '!D47 -> 560000
F55: Valor taxas a pagar no passeio: | H55: =+VLOOKUP(G45,'TARIFAS '!$A$3:$O$239,8,FALSE)*G52 -> 68000
F62: Data: | G62: =+'CONF '!A8 -> 45785
F64: Tour: | G64: =+'CONF '!B8 -> Walking Tour + Castillo San Felipe 09:00 1PAX
F66: Embarque: | G66: =+VLOOKUP(G64,'TARIFAS '!$A$3:$N$239,7,FALSE) -> Apresentar-se na recepção do hotel
F70: Titular da Reserva: | G70: =+'CONF '!$B$3 -> 0
F71: Nº de pessoas: | G71: =+'CONF '!$D$2 -> 2
F73: Valor a pagar no passeio: | H73: =+'CONF '!D48 -> 1000000
F74: Valor taxas a pagar no passeio: | H74: =+VLOOKUP(G64,'TARIFAS '!$A$3:$O$239,8,FALSE)*G71 -> 0
F81: Data: | G81: =+'CONF '!A9 -> 45786
F83: Tour: | G83: =+'CONF '!B9 -> Isla Palma
F85: Embarque: | G85: =+VLOOKUP(G83,'TARIFAS '!$A$3:$N$239,7,FALSE) -> Apresentar-se na porta 02 da Marina la Bodeguita, onde a pessoa responsável pelo embarque e dará o suporte no embarque.
F89: Titular da Reserva: | G89: =+'CONF '!$B$3 -> 0
F90: Nº de pessoas: | G90: =+'CONF '!$D$2 -> 2
F92: Valor a pagar no passeio: | H92: =+'CONF '!D49 -> 700000
F93: Valor taxas a pagar no passeio: | H93: =+VLOOKUP(G83,'TARIFAS '!$A$3:$O$239,8,FALSE)*G90 -> 58000
F100: Data: | G100: =+'CONF '!A10 -> 45611
F102: Tour: | G102: =+'CONF '!B10 -> PAU´E
F104: Embarque: | G104: =+VLOOKUP(G102,'TARIFAS '!$A$3:$N$239,7,FALSE) -> Apresentar-se na porta 04 da Marina la Bodeguita.
F108: Titular da Reserva: | G108: =+'CONF '!$B$3 -> 0
F109: Nº de pessoas: | G109: =+'CONF '!$D$2 -> 2
...

Sheet Datos
B3: Entrada PP | C3: Entrada TOT | D3: Saldo | E3: SaldoTOT
B4: =VLOOKUP('CONF '!B5,'TARIFAS '!$A$3:$N$239,4,FALSE) -> 100000 | C4: =+B4*'CONF '!$D$2 -> 200000 | D4: =VLOOKUP('CONF '!B5,'TARIFAS '!$A$3:$N$239,5,FALSE) -> 80000 | E4: =+D4*'CONF '!$D$2 -> 160000 | G4: =+B4+D4-'CONF '!C5 -> 0
B5: =VLOOKUP('CONF '!B6,'TARIFAS '!$A$3:$N$239,4,FALSE) -> 350000 | C5: =+B5*'CONF '!$D$2 -> 700000 | D5: =VLOOKUP('CONF '!B6,'TARIFAS '!$A$3:$N$239,5,FALSE) -> 0 | E5: =+D5*'CONF '!$D$2 -> 0 | G5: =+B5+D5-'CONF '!C6 -> 0
B6: =VLOOKUP('CONF '!B7,'TARIFAS '!$A$3:$N$239,4,FALSE) -> 110000 | C6: =+B6*'CONF '!$D$2 -> 220000 | D6: =VLOOKUP('CONF '!B7,'TARIFAS '!$A$3:$N$239,5,FALSE) -> 280000 | E6: =+D6*'CONF '!$D$2 -> 560000 | G6: =+B6+D6-'CONF '!C7 -> 0
B7: =VLOOKUP('CONF '!B8,'TARIFAS '!$A$3:$N$239,4,FALSE) -> 0 | C7: =+B7*'CONF '!$D$2 -> 0 | D7: =VLOOKUP('CONF '!B8,'TARIFAS '!$A$3:$N$239,5,FALSE) -> 500000 | E7: =+D7*'CONF '!$D$2 -> 1000000 | G7: =+B7+D7-'CONF '!C8 -> 0
B8: =VLOOKUP('CONF '!B9,'TARIFAS '!$A$3:$N$239,4,FALSE) -> 180000 | C8: =+B8*'CONF '!$D$2 -> 360000 | D8: =VLOOKUP('CONF '!B9,'TARIFAS '!$A$3:$N$239,5,FALSE) -> 350000 | E8: =+D8*'CONF '!$D$2 -> 700000 | G8: =+B8+D8-'CONF '!C9 -> 0
B9: =VLOOKUP('CONF '!B10,'TARIFAS '!$A$3:$N$239,4,FALSE) -> 100000 | C9: =+B9*'CONF '!$D$2 -> 200000 | D9: =VLOOKUP('CONF '!B10,'TARIFAS '!$A$3:$N$239,5,FALSE) -> 350000 | E9: =+D9*'CONF '!$D$2 -> 700000 | G9: =+B9+D9-'CONF '!C10 -> 0
B10: =VLOOKUP('CONF '!B11,'TARIFAS '!$A$3:$N$239,4,FALSE) -> 70000 | C10: =+B10*'CONF '!$D$2 -> 140000 | D10: =VLOOKUP('CONF '!B11,'TARIFAS '!$A$3:$N$239,5,FALSE) -> 370000 | E10: =+D10*'CONF '!$D$2 -> 740000 | G10: =+B10+D10-'CONF '!C11 -> 0
B11: =VLOOKUP('CONF '!B12,'TARIFAS '!$A$3:$N$239,4,FALSE) -> 120000 | C11: =+B11*'CONF '!$D$2 -> 240000 | D11: =VLOOKUP('CONF '!B12,'TARIFAS '!$A$3:$N$239,5,FALSE) -> 370000 | E11: =+D11*'CONF '!$D$2 -> 740000 | G11: =+B11+D11-'CONF '!C12 -> 0
B12: =VLOOKUP('CONF '!B13,'TARIFAS '!$A$3:$N$239,4,FALSE) -> 1350000 | C12: =+B12*'CONF '!$D$2 -> 2700000 | D12: =VLOOKUP('CONF '!B13,'TARIFAS '!$A$3:$N$239,5,FALSE) -> 1350000 | E12: =+D12*'CONF '!$D$2 -> 2700000 | G12: =+B12+D12-'CONF '!C13 -> -1000000
B13: =VLOOKUP('CONF '!B14,'TARIFAS '!$A$3:$N$239,4,FALSE) -> 520000 | C13: =+B13*'CONF '!$D$2 -> 1040000 | D13: =VLOOKUP('CONF '!B14,'TARIFAS '!$A$3:$N$239,5,FALSE) -> 1180000 | E13: =+D13*'CONF '!$D$2 -> 2360000 | G13: =+B13+D13-'CONF '!C14 -> 0
B14: =VLOOKUP('CONF '!B15,'TARIFAS '!$A$3:$N$239,4,FALSE) -> 100000 | C14: =+B14*'CONF '!$D$2 -> 200000 | D14: =VLOOKUP('CONF '!B15,'TARIFAS '!$A$3:$N$239,5,FALSE) -> 80000 | E14: =+D14*'CONF '!$D$2 -> 160000 | G14: =+B14+D14-'CONF '!C15 -> 0
B15: =VLOOKUP('CONF '!B16,'TARIFAS '!$A$3:$N$239,4,FALSE) -> 520000 | C15: =+B15*'CONF '!$D$2 -> 1040000 | D15: =VLOOKUP('CONF '!B16,'TARIFAS '!$A$3:$N$239,5,FALSE) -> 1180000 | E15: =+D15*'CONF '!$D$2 -> 2360000 | G15: =+B15+D15-'CONF '!C16 -> 0
... B20: =VLOOKUP('CONF '!B21,'TARIFAS '!$A$3:$N$239,4,FALSE) -> 100000 | C20: =+B20*'CONF '!$D$2 -> 200000 | D20: =VLOOKUP('CONF '!B21,'TARIFAS '!$A$3:$N$239,5,FALSE) -> 350000 | E20: =+D20*'CONF '!$D$2 -> 700000 | G20: =+B20+D20-'CONF '!C21 -> 0
B21: =52000*7 -> 364000 | D21: =210000+240000+15*27000 -> 855000 | E21: =+D4*7 -> 560000
B24: =+C24-B21 -> -99000 | C24: =160000*7-D21 -> 265000 | D24: =+D21/15 -> 57000
A25: =+'CONF '!D25+'CONF '!D26 -> 35220000 | C25: =+C24-15000*7 -> 160000
A29: Entrada: COP 21.202.000 no cambio 21/08/2024 = R$ 2.222,46 Dados para depósito Banco Inter Juliana Rotta 3 Pix CNPJ: 14.909.728.0001/45
A37: =+CONCATENATE("Entrada: ",TEXT('CONF '!$B$30,"COP #,#")," no cambio ",TEXT('CONF '!$C$31,"dd/mm/yyyy")," = ",TEXT('CONF '!$D$30,"R$ #,#.#0"), " Dados para depósito Banco Inter Juliana Rotta 3 Pix CNPJ: 14.909.728.0001/45") -> Entrada: COP 13880000, no cambio 14/02/2026 = R$ 2222,455 Dados para depósito Banco Inter Juliana Rotta 3 Pix CNPJ: 14.909.728.0001/45

Sheet TARIFAS 
A1: 1 | B1: $ 2 | C1: 3 | D1: $ 4 | E1: 5 | F1: $ 6 | G1: 7 | H1: $ 8 | I1: 9 | J1: $ 10
B2: TET | C2: PVP | D2: ENTRADA | E2: NETO | F2: TEXTOS | G2: LOCAL | H2: VALOR TAXAS | I2: TEXTO TAXAS | J2: HORA | N2: Voucher | O2: taxas
A3: - | B3: 0 | C3: 0 | D3: 0 | E3: 0 | F3: 0 | G3: 0 | H3: 0
A4: Aluguel De Moto Elétrica | B4: 160000 | C4: 70000 | D4: 104000 | E4: 56000 | F4: Para passear sem passar calor e curtir o melhor de Cartagena em grande estilo. Apresentar-se na hora reservada na Cidade Amuralhada, Calle 2a de Badillo 36 – 54 - 58 P 1 emabixo do hostal Badillo Inclui Passeio de 60min Capacete Treinamento – tempo não descontado do tour Hidratação Valor do saldo a pagar: Na hora de realizar o registro em Ecoway realizar o pagamento de COP 56.000 referente ao aluguel para uma pessoa. | G4: Apresentar-se na Cidade Amuralhada, Calle 2a de Badillo 36 – 54 - 58 P 1 emabixo do hostal Badillo Diagonal ao Restaurante La Vitrola | H4: 0
A5: Aluguel De Moto Elétrica 2 Pessoas | B5: 180000 | C5: 100000 | D5: 100000 | E5: 80000 | F5: Para passear sem passar calor e curtir o melhor de Cartagena em grande estilo. Apresentar-se na hora reservada naCidade Amuralhada, Calle 2a de Badillo 36 – 54 - 58 P 1 emabixo do hostal Badillo Inclui Passeio de 60min Capacete Treinamento – tempo não descontado do tour Hidratação Valor do saldo a pagar: Na hora de realizar o registro em Ecoway realizar o pagamento de COP 80.000 referente ao aluguel para duas pessoas. | G5: Apresentar-se na Cidade Amuralhada, Calle 2a de Badillo 36 – 54 - 58 P 1 emabixo do hostal Badillo Diagonal ao Restaurante La Vitrola | H5: 0
A6: Aula De Salsa | B6: 120000 | C6: 250000 | D6: =B6-E6 -> 35000 | E6: 85000 | F6: Aula de salsa para aprender a bailar o ritmo tipico colombiano e conhecer mais da cultura localApresentar-se as 17hs no Lunático Cooking Studio na Calle del Pedregal n 29, no Bairro de Getsemani. Inclui: Garrafa de agua ou Mojito Valor a pagar no passeio No dia da aula realizar o pagamento de COP 85.000 referente ao saldo por pessoa no dinheiro. | G6: Apresentar-se no Lunático Cooking Studio na Calle del Pedregal n 29, no Bairro de Getsemani. | H6: 0 | J6: 17:00
A7: Aula De Salsa Criança | B7: 90000 | C7: 250000 | D7: =B7-E7 -> 47500 | E7: 42500 | F7: Aula de salsa para aprender a bailar o ritmo tipico colombiano e conhecer mais da cultura localApresentar-se as 17hs no Lunático Cooking Studio na Calle del Pedregal n 29, no Bairro de Getsemani. Inclui: Garrafa de agua ou Mojito Valor a pagar no passeio No dia da aula realizar o pagamento de COP 42.500 referente ao saldo por pessoa no dinheiro. | G7: Apresentar-se no Lunático Cooking Studio na Calle del Pedregal n 29, no Bairro de Getsemani. | H7: 0 | J7: 17:00
A8: Bonavida | B8: 440000 | C8: 370000 | D8: =B8-E8 -> 70000 | E8: 370000 | F8: Um passeio de catamarã com paradas para mergulho e snorkel nas águas das baías das Ilhas do Rosário. Ideal para quem gosta de nadar e navegar sem paradas em praias. Apresentar-se 08am na Marina La Bodeguita porta 3 onde o catamarã Bona Vida estará ancorado, e a tripulação dará toda assistência no embarque as 8:30am Aproximadamente às 14h40 iniciaremos nosso retorno ao cais Los Pegasos. desembarcar às 16h00. Inclui: Petiscos (Empanadas, quibbe e palitos de queijo). Open bar de bebidas não alcoólicas (água, refrigerante, limonada natural e suco temperado). Almoço (Arroz com frutos do mar ou arroz com legumes). Máscaras e tubos para mergulho com snorkel (não guiado). Serviço de bar a bordo (Venda de bebidas não alcoólicas). Valor do saldo a pagar: Para garantir a reserva, é necessário pagar o saldo de COP 370.000 (COP 350.000 passeio + COP 23.000 taxas), a través do link de pagamento com cartão de crédito enviado por mensagem, referente ao saldo por pessoa e taxas portuárias no deck de Bonavida. O pagamento é não reembolsável. | G8: Apresentar-se na Marina La Bodeguita porta 3 onde o catamarã Bona Vida estará ancorado. A tripulação dará toda assistência no embarque. Retorno para a Marina Los Pegasos às 16:00. | H8: 26500 | I8: Pagar a taxas portuárias COP 26.500 (valor por pessoa – somente em dinheiro. Valor sujeito a alterações) | J8: 08:30
A9: Bonavida Criança | B9: 290000 | C9: 125000 | D9: 105000 | E9: 185000 | F9: Um passeio de catamarã com paradas para mergulho e snorkel nas águas das baías das Ilhas do Rosário. Ideal para quem gosta de nadar e navegar sem paradas em praias. Apresentar-se no deck de madeira ao lado da Marina La Bodeguita as 08am onde o catamarã Bona Vida estará ancorado e a tripulação dará toda assistência no embarque. Inclui Taxas portuárias Suco de boas vindas Almoço – opção de arroz de marisco, frango ou vegetariano com salada. Acompanha suco Assentos e redes para tomar sol Snorkel e máscaras Valor do saldo a pagar: No dia do passeio, realizar o pagamento de COP 205.000 só em cartão (COP 185.000 passeio + COP 23.000 taxas), referente ao saldo por pessoa e taxas portuárias no deck de Bonavida | G9: Apresentar-se na Marina La Bodeguita porta 3 onde o catamarã Bona Vida estará ancorado. A tripulação dará toda assistência no embarque. Retorno para a Marina Los Pegasos às 16:00. | H9: 26500 | I9: Pagar a taxas portuárias COP 26.500 (valor por pessoa – somente em dinheiro. Valor sujeito a alterações) | J9: 08:30
A10: Bora Bora Bc | B10: 390000 | C10: 370000 | D10: =B10-E10 -> 110000 | E10: 280000 | F10: Excelente opção aproveitar um dia espetacular na Praia ouvindo boa música e com uma paisagem impressionante. Apresentar-se as 07:30 na porta 03 da Marina la Bodeguita. Pagar a taxas portuárias COP 26.500 + Seguro 5.000 = 31.500COP (valor por pessoa – somente em dinheiro. Valor sujeito a alterações) Inclui Ida e volta em lancha rápida Coquetel de boas-vindas Almoço - opção: peixe, frango ou vegetariano, com arroz de coco, salada e banana frita. Acompanha suco Camas de praia e DJ Obs: no caso de ser um passageiro, dependendo da ocupação, poderão ser acomodados em espreguiçadeiras ao inves de camas de praia Nao Inclui: cama da primeira fila e a mesma deve ser contratada na hora do embarque direto com bora (custo de COP 80.000 aproximadamente) Valor do saldo a pagar: Para garantir a reserva, pagamento do saldo de COP 250.000 por pessoa através do link de pagamento com cartão de crédito enviado por mensagem, não reembolsável | G10: Apresentar-se na porta 03 da Marina la Bodeguita. | H10: 34000 | I10: Pagar a taxas portuárias COP 29.000 + Seguro COP 5.000 (valor por pessoa – somente em dinheiro. Valor sujeito a alterações) | J10: 07:20
A11: Bora Bora Vip | B11: 490000 | C11: 470000 | D11: =B11-E11 -> 120000 | E11: 370000 | F11: Excelente opção aproveitar um dia espetacular na praia com boa música e paisagem impressionante. Apresentar-se as 07:20 na porta 03 da Marina la Bodeguita. Pagar a taxas portuárias COP 26.500 + Seguro COP 5.000 = COP 31.500(valor por pessoa – somente em dinheiro. Valor sujeito a alterações) Inclui Ida e volta em lancha rápida Coquetel de boas-vindas Almoço - opções: paella, frango ou vegetariano. Acompanha suco Cama de praia e toalha Lounge com A/C, DJ, praia VIP e acesso ao Bora Bora Beach Club Nao Inclui: cama da primeira fila e a mesma deve ser contratada na hora do embarque direto com bora (custo de COP 80.000 aproximadamente) Valor do saldo a pagar: Para garantir a reserva, pagamento do saldo de COP 330.000 por pessoa através do link de pagamento com cartão de crédito enviado por mensagem, não reembolsável | G11: Apresentar-se na porta 03 da Marina la Bodeguita. | H11: 34000 | I11: Pagar a taxas portuárias COP 29.000 + Seguro COP 5.000 (valor por pessoa – somente em dinheiro. Valor sujeito a alterações) | J11: 07:20
A12: Coralina Isleño | B12: 420000 | C12: 380000 | D12: =B12-E12 -> 130000 | E12: 290000 | F12: Um dia de charme, elegância e atendimento excelente em decks semi privativos com a beleza do Caribe a seus pés. Ideal para quem gosta de nadar e fazer snorkel. Apresentar-se na recepção do hotel para esperar a van de Coralina Island. Para hotéis em Bocagrande a partir de 07:45am e hotéis na cidade amuralhada a partir de 08 Inclui Taxas portuárias Traslado de ida a Marina la Bodeguita Ida e volta em lancha rápida Taça de vinho de boas-vindas Almoço a la carte e sobremesa. Camas de praia e toalha Valor do saldo a pagar: Na ilha no final do passeio realizar o pagamento de COP 270.000 + Pagar as tasas portuarias COP 26.500 + Seguro COP 5.000 (valor sujeito a altearções) = COP 276.000 por pessoa referente ao saldo do passeio e taxas portuárias no dinheiro ou cartão de crédito. | G12: Apresentar-se na recepção do hotel para esperar a van de Coralina Island. Para hotéis em Bocagrande a partir de 07:45am e hotéis na cidade amuralhada a partir de 08am | H12: 34000 | I12: Pagar a taxas portuárias COP 29.000 + Seguro COP 5.000 (valor por pessoa – somente em dinheiro. Valor sujeito a alterações) | J12: 07:45
A13: Coralina VIP | B13: 580000 | C13: 530000 | D13: =B13-E13 -> 150000 | E13: 430000 | F13: Um dia de charme, elegância e atendimento excelente em decks semi privativos com a beleza do Caribe a seus pés. Ideal para quem gosta de nadar e fazer snorkel. Apresentar-se na recepção do hotel para esperar a van de Coralina Island. Para hotéis em Bocagrande a partir de 07:45am e hotéis na cidade amuralhada a partir de 08am na recepção. Inclui Taxas portuárias Traslado de ida a Marina la Bodeguita Ida e volta em lancha rápida Taça de vinho de boas-vindas Almoço a la carte e sobremesa. Camas de praia e toalha Valor do saldo a pagar: Na ilha no final do passeio realizar o pagamento de COP 405.000 + Pagar a taxas portuárias COP 26.500+ Seguro COP 5.000 (valor sujeito a altearções) = COP 426.000 por pessoa referente ao saldo do passeio e taxas portuárias no dinheiro ou cartão de crédito. | G13: Apresentar-se na recepção do hotel para esperar a van de Coralina Island. Para hotéis em Bocagrande a partir de 07:45am e hotéis na cidade amuralhada a partir de 08am na recepção. | H13: 34000 | I13: Pagar a taxas portuárias COP 29.000 + Seguro COP 5.000 (valor por pessoa – somente em dinheiro. Valor sujeito a alterações) | J13: 07:45
A14: Degustação De Cervejas | B14: 250000 | C14: 185000 | D14: 20000 | E14: 230000 | F14: Degustação de cervejas artesanais Colombianas Uma imersão na cena das cervejas colombianas, seus sabores, preparos e produção. Degustação de 10 cervejas diferentes Acompanhada com ceviche e sanduíche Atividade bilíngue (inglês/espanhol) Valor de saldo a pagar por pessoa: .000 pesos Horário das 15 as 16:30h De terça a sábado Mínimo de 2 pessoas – para grupos consultar valores e horarios | G14: 0 | H14: 0
A15: Degustação De Rum Colombiano | B15: 250000 | C15: 185000 | D15: 65000 | E15: 185000 | F15: 0 | G15: 0 | H15: 0
A16: Degustação De Rum Colombiano | B16: 300000 | C16: 185000 | D16: 70000 | E16: 230000 | F16: Aprender sobre o universo do rum colombiano com chocolotes para harmonizar sabores. Degustação de variedade runs colombianos em diferentes preparos e chocolates locais para ressaltar o sabor da bebida nacional Atividade bilíngue (inglês/espanhol) Valor do saldo a pagar: No dia da aula realizar o pagamento de COP 230.000 por pessoa referente ao saldo da atividade no dinheiro. | G16: 0 | H16: 0
A17: Ensaio Fotográfico | B17: 550000 | C17: 400000 | D17: 190000 | E17: 360000 | F17: Cartagena é uma das cidades mais bonitas do mundo, declarada Patrimônio da Unesco desde 1984. Uma sessão de fotos na cidade é a forma perfeita de eternizar os momentos especiais que famílias, casais e amigos passam por aqui. Ponto de encontro as 16:00hs na Iglesia San Pedro Claver. No dia anterior ao passeio, será enviado contato do fotógrafo. Inclui Sessão de duas horas na cidade amuralhada das 4pm as 6pm. Entrega de fotos tiradas em alta resolução e em uma pasta adicional para a Internet As fotografias incluem edição e retoque geral Uma foto impressa, tamanho 20 x30 (como uma amostra da qualidade do trabalho) Envio por We Transfer (alta resolução) e pelo email (baixa resolução) Média de 50 a 60 fotos selecionadas Valor a pagar no passeio: No local do passeio realizar o pagamento de COP 360.000 referente ao saldo do passeio no dinheiro. | G17: Apresentar-se na Iglesia San Pedro Claver. No dia anterior ao passeio, será enviado contato do fotógrafo. | H17: 0
A18: Experiência Culinária | B18: 300000 | C18: 250000 | D18: 50000 | E18: 250000 | F18: Descubra a identidade caribenha da gastronomia de Cartagena preparando uma refeição de quatro tempos com um chef local em um estúdio culinário incrível com uma vista incrível da cidade. Apresentar-se as 10:30am no Lunático Cooking Studio na Calle del Pedregal n 29, no Bairro de Getsemani. Inclui: Suco de boas Vindas Ingredientes e cozinha equipada com chef local Degustação do menu final com cerveja ou vinho Valor do saldo a pagar:No dia da aula realizar o pagamento de COP 250.000 por pessoa referente ao saldo da atividade no dinheiro. | G18: Apresentar-se no Lunático Cooking Studio na Calle del Pedregal n 29, no Bairro de Getsemani. | H18: 0 | J18: 10:30
A19: Experiência Culinária Criança | B19: 240000 | C19: 250000 | D19: 115000 | E19: 125000 | F19: Descubra a identidade caribenha da gastronomia de Cartagena preparando uma refeição de quatro tempos com um chef local em um estúdio culinário incrível com uma vista incrível da cidade. Apresentar-se as 10:30am no Lunático Cooking Studio na Calle del Pedregal n 29, no Bairro de Getsemani. Inclui: Suco de boas Vindas Ingredientes e cozinha equipada com chef local Degustação do menu final com bebida Valor do saldo a pagar:No dia da aula realizar o pagamento de COP 125.000 por pessoa referente ao saldo da atividade no dinheiro. | G19: Apresentar-se no Lunático Cooking Studio na Calle del Pedregal n 29, no Bairro de Getsemani. | H19: 0 | J19: 10:30
A20: Fenix Cena | B20: 290000 | C20: 245000 | D20: 95000 | E20: 195000 | F20: Praia de areia branca, palmeiras e camas de praia com um piscina de frente para o Caribe a só 10 minutos de Cartagena Apresentar-se as 18:40 na Porta 02 da Marina La Bodeguita. Pagar os impostos de COP 14.000 por pessoa . Dentro da marina, a pessoa responsável de Fenix Beach dará assistência para o embarque. Inclui: Bebida de boas vindas Jantar - prato a la carte do menu (exceto Costillas al Whisky, Pago Rojo, Cazuela de Mariscos e a Posta Cartagenera) e sobremesa do dia Dj, fogueira e mesa no bar ou restaurante Valor do saldo a pagar: No Fenix realizar o pagamento de COP 195.000 referente ao saldo do passeio por pessoa no dinheiro ou cartão de crédito. | G20: Apresentar-se na Porta 02 da Marina La Bodeguita. Dentro da marina, a pessoa responsável de Fenix Beach dará assistência para o embarque. | H20: 14000 | I20: Pagar as taxas de COP 14.000 por pessoa | J20: 18:40
A21: Fenix Cena Criança | B21: 300000 | C21: 245000 | D21: 150000 | E21: 150000 | F21: Praia de areia branca, palmeiras e camas de praia com um piscina de frente para o Caribe a só 10 minutos de Cartagena Apresentar-se as 18:40 na Porta 02 da Marina La Bodeguita. Pagar os impostos de COP 14.000 por pessoa . Dentro da marina, a pessoa responsável de Fenix Beach dará assistência para o embarque. Inclui: Bebida de boas vindas Jantar - prato a la carte do menu (exceto Costillas al Whisky, Pago Rojo, Cazuela de Mariscos e a Posta Cartagenera) e sobremesa do dia Dj, fogueira e mesa no bar ou restaurante Valor do saldo a pagar: No Fenix realizar o pagamento de COP 150.000 referente ao saldo do passeio por pessoa no dinheiro ou cartão de crédito. | G21: Apresentar-se na Porta 02 da Marina La Bodeguita. Dentro da marina, a pessoa responsável de Fenix Beach dará assistência para o embarque. | H21: 14000 | I21: Pagar as taxas de COP 14.000 por pessoa | J21: 18:40
A22: Fenix Decoração na praia | B22: 320000 | C22: 100000 | D22: 170000 | E22: 150000 | F22: Para garantir a reserva, pagamento do saldo de COP 150.000 por através do link de pagamento com cartão de crédito enviado por mensagem, não reembolsável | G22: 0 | H22: 0
A23: Fenix Decoração ninho | B23: 320000 | C23: 100000 | D23: 170000 | E23: 150000 | F23: Para garantir a reserva, pagamento do saldo de COP 150.000 por através do link de pagamento com cartão de crédito enviado por mensagem, não reembolsável | G23: 0 | H23: 0
A24: Fenix Decoração ninho 5/10 pax | B24: 450000 | C24: 100000 | D24: 200000 | E24: 250000 | F24: Para garantir a reserva, pagamento do saldo de COP 250.000 por através do link de pagamento com cartão de crédito enviado por mensagem, não reembolsável | G24: 0 | H24: 0
A25: Fenix Pasadia | B25: 390000 | C25: 195000 | D25: 180000 | E25: 210000 | F25: Praia de areia branca, palmeiras e camas de praia com um piscina de frente para o Caribe a só 10 minutos de Cartagena Apresentar-se na porta 01 da Marina la Bodeguita. Pagar a taxas portuárias COP 14.000 (valor por pessoa– somente em dinheiro. Sujeito a alteração) na porta 01 para entrar na Marina. Inclui: Bebida de boas vindas Almoço - opção: peixe, frango ou vegano, com arroz de coco, salada e banana frita. Acompanha suco e sobremesa Camas de praia, piscina, quadra de volêi Valor do saldo a pagar: No guichê de Fenix na hora do registro realizar o pagamento de COP 210.000 referente ao saldo do passeio por pessoa no dinheiro ou cartão de crédito. | G25: Apresentar-se na porta 01 da Marina la Bodeguita. | H25: 14000 | I25: Pagar a taxas portuárias COP 14.000 (valor por pessoa– somente em dinheiro. Sujeito a alteração) na porta 01 para entrar na Marina.
A26: Fenix Pasadia Criança | F26: Praia de areia branca, palmeiras e camas de praia com um piscina de frente para o Caribe a só 10 minutos de Cartagena Apresentar-se na porta 01 da Marina la Bodeguita. Pagar a taxas portuárias COP 14.000 (valor por pessoa– somente em dinheiro. Sujeito a alteração) na porta 01 para entrar na Marina. Inclui: Bebida de boas vindas Almoço - opção: peixe, frango ou vegano, com arroz de coco, salada e banana frita. Acompanha suco e sobremesa Camas de praia, piscina, quadra de volêi Valor do saldo a pagar: No guichê de Fenix na hora do registro realizar o pagamento de COP 210.000 referente ao saldo do passeio por pessoa no dinheiro ou cartão de crédito. | G26: Apresentar-se na porta 01 da Marina la Bodeguita. | H26: 14000 | I26: Pagar a taxas portuárias COP 14.000 (valor por pessoa– somente em dinheiro. Sujeito a alteração) na porta 01 para entrar na Marina.
A27: Fenix Pasadia+Cena | F27: 0 | G27: 0 | H27: 14000
A28: Insta Tour Ciudad Amurallada | B28: 190000 | C28: 0 | D28: 75000 | E28: 115000 | F28: Cada rua na Cidade Amuralhada tem o seu encanto mas os spots mais INSTAGRAMÁVEIS você visita em nosso tour. Apresentar-se as 16:30hs na Iglesia San Pedro Claver para encontrar com o guia. Inclui Guia turístico profissional em português Caminhada nas calles mais Instagramáveis Subida na Cúpula da Igreja Pôr do sol e Drink em rooftop da cidade Tratamento digital de 5 fotos tiradas no celular Valor a pagar no passeio No dia do passeio realizar o pagamento de COP 115.000 referente ao saldo do passeio por pessoa somente em dinheiro | G28: Apresentar-se na Iglesia San Pedro Claver para encontrar com o guia. | H28: 0 | J28: 16:30
A29: Insta Tour Ciudad Amurallada Hotel | B29: 190000 | C29: 0 | D29: 75000 | E29: 115000 | F29: Cada rua na Cidade Amuralhada tem o seu encanto mas os spots mais INSTAGRAMÁVEIS você visita em nosso tour. Apresentar-se as 16:30hs na recepção do hotel para encontrar com o guia. Inclui Guia turístico profissional em português Caminhada nas calles mais Instagramáveis Subida na Cúpula da Igreja Pôr do sol e Drink em rooftop da cidade Tratamento digital de 5 fotos tiradas no celular Valor a pagar no passeio No dia do passeio realizar o pagamento de COP 115.000 referente ao saldo do passeio por pessoa somente em dinheiro | G29: Apresentar-sena recepçâo do hotel para encontrar com o guia. | H29: 0 | J29: 16:30
A30: Isla Bela | B30: 360000 | C30: 310000 | D30: 120000 | E30: 240000 | F30: Um dia no paraíso com boa praia e bela paisagem. Opção ideal para quem quer sossego e gosta de nadar. Apresentar-se as 07:30 na porta 03 da Marina la Bodeguita. Pagar a taxas portuárias + seguro COP 31.500 (valor por pessoa– somente em dinheiro) Inclui Ida e volta em lancha rápida Coquetel de Boas-vindas (não alcoólico) Almoço - opção: peixe, frango ou vegetariano, com arroz de coco, salada e banana frita. Acompanha suco Cadeiras de praia Opcional Visita ao Oceanário (entrada não incluída) – avisar diretamente na lancha na hora do embarque se desejar visitar o Oceanário. Valor do saldo a pagar: Para garantir a reserva, pagamento do saldo de COP 240.000 por pessoa através do link de pagamento com cartão de crédito enviado por mensagem, não reembolsável | G30: Apresentar-se na porta 03 da Marina la Bodeguita. | H30: 31500 | I30: Pagar a taxas portuárias COP 26.500 + Seguro COP 5.000 (valor por pessoa – somente em dinheiro. Valor sujeito a alterações) | J30: 07:30
A31: Isla Bela Criança | B31: 320000 | C31: 150000 | D31: 100000 | E31: 220000 | F31: Um dia no paraíso com boa praia e bela paisagem. Opção ideal para quem quer sossego e gosta de nadar. Apresentar-se as 07:30 na porta 03 da Marina la Bodeguita. Pagar a taxas portuárias+ seguro COP 31.500 (valor por pessoa– somente em dinheiro) Inclui Ida e volta em lancha rápida Coquetel de Boas-vindas (não alcoólico) Almoço - opção: peixe, frango ou vegetariano, com arroz de coco, salada e banana frita. Acompanha suco Cadeiras de praia. Opcional Visita ao Oceanário (entrada não incluída) – avisar diretamente na lancha na hora do embarque se desejar visitar o Oceanário. Valor do saldo a pagar: Para garantir a reserva, pagamento do saldo de COP 220.000 por pessoa através do link de pagamento com cartão de crédito enviado por mensagem, não reembolsável | G31: Apresentar-se na porta 03 da Marina la Bodeguita. | H31: 31500 | I31: Pagar a taxas portuárias COP 26.500 + Seguro COP 5.000 (valor por pessoa – somente em dinheiro. Valor sujeito a alterações) | J31: 07:30
A32: Isla Bela | B32: 390000 | C32: 310000 | D32: =B32-E32 -> 125000 | E32: 265000 | F32: Um dia no paraíso com boa praia e bela paisagem. Opção ideal para quem quer sossego e gosta de nadar. Apresentar-se as 07:30 na porta 03 da Marina la Bodeguita. Pagar a taxas portuárias + seguro COP 31.500 (valor por pessoa– somente em dinheiro) Inclui Ida e volta em lancha rápida Coquetel de Boas-vindas (não alcoólico) Almoço - opção: peixe, frango ou vegetariano, com arroz de coco, salada e banana frita. Acompanha suco Cadeiras de praia Opcional Visita ao Oceanário (entrada não incluída) – avisar diretamente na lancha na hora do embarque se desejar visitar o Oceanário. Valor do saldo a pagar: Para garantir a reserva, pagamento do saldo de COP 240.000 por pessoa através do link de pagamento com cartão de crédito enviado por mensagem, não reembolsável | G32: Apresentar-se na porta 03 da Marina la Bodeguita. | H32: 34000 | I32: Pagar a taxas portuárias COP 29.000 + Seguro COP 5.000 (valor por pessoa – somente em dinheiro. Valor sujeito a alterações) | J32: 07:30
A33: Isla Bela Criança | B33: 300000 | C33: 150000 | D33: =B33-E33 -> 60000 | E33: 240000 | F33: Um dia no paraíso com boa praia e bela paisagem. Opção ideal para quem quer sossego e gosta de nadar. Apresentar-se as 07:30 na porta 03 da Marina la Bodeguita. Pagar a taxas portuárias+ seguro COP 31.500 (valor por pessoa– somente em dinheiro) Inclui Ida e volta em lancha rápida Coquetel de Boas-vindas (não alcoólico) Almoço - opção: peixe, frango ou vegetariano, com arroz de coco, salada e banana frita. Acompanha suco Cadeiras de praia. Opcional Visita ao Oceanário (entrada não incluída) – avisar diretamente na lancha na hora do embarque se desejar visitar o Oceanário. Valor do saldo a pagar: Para garantir a reserva, pagamento do saldo de COP 220.000 por pessoa através do link de pagamento com cartão de crédito enviado por mensagem, não reembolsável | G33: Apresentar-se na porta 03 da Marina la Bodeguita. | H33: 34000 | I33: Pagar a taxas portuárias COP 29.000 + Seguro COP 5.000 (valor por pessoa – somente em dinheiro. Valor sujeito a alterações) | J33: 07:30
A34: Isla Del Encanto | B34: 370000 | C34: 250000 | D34: 138000 | E34: 232000 | F34: Localizada em Baru e com boa estrutura de hotel. Ideal para famílias e com crianças pequenas. Apresentar-se na recepção do hotel para esperar a van a partir das 08:15am. Pagar a taxas portuárias COP 23.000 (valor por pessoa – somente em dinheiro. Valor sujeito a alterações) na van para entrar na Marina. Inclui Ida e volta em lancha rápida Suco de boas-vindas Almoço - opção: peixe, frango ou vegetariano, com arroz de coco, salada e banana frita. Acompanha suco Cadeiras de praia e toalhas Valor do saldo a pagar: No guichê de Isla del Encanto na hora do registro realizar o pagamento de COP 232.000 referente ao saldo do passeio por pessoa no dinheiro ou cartão de crédito. | G34: Apresentar-se na recepção do hotel para esperar a van. | H34: 26500 | I34: Pagar a taxas portuárias COP 26.500(valor por pessoa– somente em dinheiro) na van para entrar na Marina. | J34: 08:15
A35: Isla Del Encanto Criança até 10 anos | B35: 310000 | C35: 140000 | D35: 190000 | E35: 120000 | F35: Localizada em Baru e com boa estrutura de hotel. Ideal para famílias e com crianças pequenas. Apresentar-se na recepção do hotel para esperar a van a partir das 08:15am. Pagar a taxas portuárias COP 23.000 (valor por pessoa – somente em dinheiro. Valor sujeito a alterações) na van para entrar na Marina. Inclui Ida e volta em lancha rápida Suco de boas-vindas Almoço - opção: peixe, frango ou vegetariano, com arroz de coco, salada e banana frita. Acompanha suco Cadeiras de praia e toalhas Valor do saldo a pagar: No guichê de Isla del Encanto na hora do registro realizar o pagamento de COP 120.000 referente ao saldo do passeio por pessoa no dinheiro ou cartão de crédito. | G35: Apresentar-se na recepção do hotel para esperar a van. | H35: 26500 | I35: Pagar a taxas portuárias COP 26.500(valor por pessoa– somente em dinheiro) na van para entrar na Marina. | J35: 08:15
A36: Isla Del Encanto Criança até 4 anos | B36: 270000 | C36: 90000 | D36: 170000 | E36: 100000 | F36: Localizada em Baru e com boa estrutura de hotel. Ideal para famílias e com crianças pequenas. Apresentar-se na recepção do hotel para esperar a van a partir das 08:15am. Pagar a taxas portuárias COP 23.000 (valor por pessoa – somente em dinheiro. Valor sujeito a alterações) na van para entrar na Marina. Inclui Ida e volta em lancha rápida Suco de boas-vindas Almoço - opção: peixe, frango ou vegetariano, com arroz de coco, salada e banana frita. Acompanha suco Cadeiras de praia e toalhas Valor do saldo a pagar: No guichê de Isla del Encanto na hora do registro realizar o pagamento de COP 100.000 referente ao saldo do passeio por pessoa no dinheiro ou cartão de crédito. | G36: Apresentar-se na recepção do hotel para esperar a van. | H36: 26500 | I36: Pagar a taxas portuárias COP 26.500(valor por pessoa– somente em dinheiro) na van para entrar na Marina. | J36: 08:15
A37: Isla Del Encanto TA | E37: 200000 | F37: Localizada em Baru e com boa estrutura de hotel. Ideal para famílias e com crianças pequenas. Apresentar-se na recepção do hotel para esperar a van a partir das 08:15am. Pagar a taxas portuárias COP 23.000 (valor por pessoa – somente em dinheiro. Valor sujeito a alterações) na van para entrar na Marina. Inclui Ida e volta em lancha rápida Suco de boas-vindas Almoço - opção: peixe, frango ou vegetariano, com arroz de coco, salada e banana frita. Acompanha suco Cadeiras de praia e toalhas Valor do saldo a pagar: No guichê de Isla del Encanto na hora do registro realizar o pagamento de COP 200.000 referente ao saldo do passeio por pessoa no dinheiro ou cartão de crédito. | G37: Apresentar-se na recepção do hotel para esperar a van. | H37: 26500 | I37: Pagar a taxas portuárias COP 26.500(valor por pessoa– somente em dinheiro) na van para entrar na Marina. | J37: 08:15
A38: Isla Del Pirata | B38: 330000 | C38: 200000 | D38: 170000 | E38: 160000 | F38: Um beach club para quem gosta de nadar, remar e ficar na água o dia inteiro. Perfeito para casais e amigos. Apresentar-se 08:15 no guichê 01 de Isla del Pirata na Marina la Bodeguita. Pagar a taxas portuárias COP 23.000 (valor por pessoa – somente em dinheiro. Valor sujeito a alterações) para entrar na porta 01 da Marina. Inclui Ida e volta em lancha rápida Coquetel de boas vindas Almoço - opção: peixe com arroz de coco, salada e banana frita. Ou voucher de consumo no restaurante de COP 40.000 Cadeiras de praias e toalhas Valor do saldo a pagar: No guichê de Isla de Pirata na hora do registro realizar o pagamento de COP 160.000 referente ao saldo do passeio por pessoa no dinheiro ou cartão de crédito. | G38: Apresentar-se 08:15 no guichê 01 de Isla del Pirata na Marina la Bodeguita. Pagar a taxas portuárias COP 23.000 (somente em dinheiro – valor por pessoa) para entrar na porta 01 da Marina. | H38: 26500
A39: Isla Del Pirata Criança | B39: 270000 | C39: 160000 | D39: 140000 | E39: 130000 | F39: Um beach club para quem gosta de nadar, remar e ficar na água o dia inteiro. Perfeito para casais e amigos. Apresentar-se 08:15 no guichê 01 de Isla del Pirata na Marina la Bodeguita. Pagar a taxas portuárias COP 23.000 (somente em dinheiro – valor por pessoa) para entrar na porta 01 da Marina. Inclui Ida e volta em lancha rápida Coquetel de boas vindas Almoço - opção: peixe com arroz de coco, salada e banana frita. Ou voucher de consumo no restaurante de COP 40.000 Cadeiras de praias e toalhas Valor do saldo a pagar: No guichê de Isla de Pirata na hora do registro realizar o pagamento de COP 130.000 referente ao saldo do passeio por pessoa no dinheiro ou cartão de crédito. | G39: 0 | H39: 26500
A40: Isla del Sol | B40: 420000 | C40: 370000 | D40: =B40-E40 -> 140000 | E40: 280000 | F40: Isla del Sol é excelente para famílias e casais curtirem o dia com infra estrutura de hotel e piscina Apresentar-se as 07:50 na porta 04 da Marina la Bodeguita onde a pessoa responsável pelo embarque de Isla del Sol dará o suporte no embarque. Pagar a taxas portuárias COP 26.500 (valor por pessoa – somente em dinheiro. Valor sujeito a alterações) Inclui: - Frutas tropicais de boas vindas. - Almoço típico (peixe frito ou frango, arroz com coco, mandioca frita, patacones, salada, bebidas não alcoólicas e sobremesa). - Cadeiras, guarda sol, piscina (com agua salgada), redes para descanso, - Tour panorâmico pelo Parque Nacional Natural Corales del Rosario com ida ao Oceanário (entrada opcional - não incluída) Pagamento do saldo do passeio: Para garantir a reserva, pagamento do saldo de COP 270.000 por pessoa através do link de pagamento com cartão de crédito enviado por mensagem, não reembolsável | G40: Apresentar-sena porta 04 da Marina la Bodeguita onde a pessoa responsável pelo embarque de Isla del Sol dará o suporte no embarque. | H40: 29000 | I40: Pagar a taxas portuárias COP 29.000(valor por pessoa– somente em dinheiro) na van para entrar na Marina. | J40: 07:50
...

Sheet Historico TARIFAS 
B1: 45292 | F1: 2024-2025
B2: TET | C2: PVP | D2: ENTRADA | E2: NETO | F2: TET | G2: PVP | H2: ENTRADA | I2: NETO | J2: Activo | K2: Data inicio | L2: Data fim
A3: - | B3: 0 | C3: 0 | D3: 0 | E3: 0 | F3: 0 | G3: 0 | H3: 0 | I3: 0
A4: Aluguel De Moto Elétrica | B4: 160000 | C4: 70000 | D4: 104000 | E4: 56000 | F4: 160000 | G4: 70000 | H4: 104000 | I4: 56000
A5: Adicional noturno das 21:00hs as 06:00hs
A6: Aluguel De Moto Elétrica 2 Pessoas | B6: 180000 | C6: 100000 | D6: 100000 | E6: 80000 | F6: 180000 | G6: 100000 | H6: 100000 | I6: 80000
A7: Aula De Salsa | B7: 120000 | C7: 250000 | D7: 35000 | E7: 85000 | F7: 120000 | G7: 250000 | H7: 35000 | I7: 85000 | J7: OK Geni
A8: Aula De Salsa Criança | B8: 90000 | C8: 250000 | D8: 47500 | E8: 42500 | F8: 90000 | G8: 250000 | H8: 47500 | I8: 42500 | J8: OK Geni
A9: Bonavida | B9: 440000 | C9: 370000 | D9: 123000 | E9: 370000 | F9: 440000 | G9: 370000 | H9: 123000 | I9: 370000 | J9: 2025
A10: Bonavida Criança | B10: 290000 | C10: 125000 | D10: 105000 | E10: 185000 | F10: 290000 | G10: 125000 | H10: 105000 | I10: 185000
A11: Bora Bora Bc | B11: 360000 | C11: 200000 | D11: 110000 | E11: 250000 | F11: 390000 | G11: 200000 | H11: =F11-I11 -> 110000 | I11: 280000 | J11: OK Geni
A12: Bora Bora Vip | B12: 450000 | C12: 300000 | D12: 120000 | E12: 330000 | F12: 470000 | G12: 300000 | H12: =F12-I12 -> 100000 | I12: 370000 | J12: OK Geni
A13: Consultoria Express | B13: 80 | C13: 0 | D13: 80 | F13: 80 | G13: 0 | H13: 80
A14: Coralina Isleño | B14: 390000 | C14: 360000 | D14: 120000 | E14: 270000 | F14: 420000 | G14: 380000 | H14: =F14-I14 -> 130000 | I14: 290000 | J14: OK Geni | K14: 45651 | L14: 45672
A15: Coralina VIP | B15: 540000 | C15: 505000 | D15: 135000 | E15: 405000 | F15: 580000 | G15: 530000 | H15: =G15-I15 -> 100000 | I15: 430000 | J15: OK Geni | K15: 45651 | L15: 45672
A16: Degustação De Cervejas | B16: 250000 | C16: 185000 | D16: 20000 | E16: 230000 | F16: 250000 | G16: 185000 | H16: =F16-I16 -> 20000 | I16: 230000
A17: Degustação De Rum Colombiano | B17: 250000 | C17: 185000 | D17: 65000 | E17: 185000 | F17: 250000 | G17: 185000 | H17: 65000 | I17: 185000
A18: Degustação De Rum Colombiano | B18: 300000 | C18: 185000 | D18: 70000 | E18: 230000 | F18: 300000 | G18: 185000 | H18: 70000 | I18: 230000
A19: Edição Fotografica | B19: 120 | C19: 0 | D19: 50000 | E19: -49880 | F19: 120 | G19: 0 | H19: 50000 | I19: -49880
A20: Ensaio Fotográfico | B20: 550000 | C20: 400000 | D20: 190000 | E20: 360000 | F20: 550000 | G20: 400000 | H20: 190000 | I20: 360000
A21: Experiência Culinária | B21: 300000 | C21: 250000 | D21: 50000 | E21: 250000 | F21: 300000 | G21: 250000 | H21: 50000 | I21: 250000
A22: Experiência Culinária Criança | B22: 240000 | C22: 250000 | D22: 115000 | E22: 125000 | F22: 240000 | G22: 250000 | H22: 115000 | I22: 125000
A23: Fenix Cena com ninho 10 PAX | B23: 330000 | C23: 245000 | D23: 135000 | E23: 195000 | F23: 330000 | G23: 245000 | H23: 135000 | I23: 195000
A24: Fenix Cena com ninho 15 PAX | B24: 330000 | C24: 245000 | D24: 135000 | E24: 195000 | F24: 330000 | G24: 245000 | H24: 135000 | I24: 195000
A25: Fenix Cena | B25: 290000 | C25: 245000 | D25: 95000 | E25: 195000 | F25: 290000 | G25: 245000 | H25: 95000 | I25: 195000
A26: Fenix Cena Criança | B26: 300000 | C26: 245000 | D26: 150000 | E26: 150000 | F26: 300000 | G26: 245000 | H26: 150000 | I26: 150000
A27: Fenix Decoração na praia | B27: 320000 | C27: 100000 | D27: 170000 | E27: 150000 | F27: 320000 | G27: 100000 | H27: 170000 | I27: 150000
A28: Fenix Decoração ninho | B28: 320000 | C28: 100000 | D28: 170000 | E28: 150000 | F28: 320000 | G28: 100000 | H28: 170000 | I28: 150000
... A30: Fenix Pasadia | B30: 390000 | C30: 195000 | D30: 180000 | E30: 210000 | F30: 390000 | G30: 195000 | H30: 180000 | I30: 210000
A31: Fenix Pasadia Criança
A32: Fenix Pasadia+Cena
A33: Insta Tour Ciudad Amurallada | B33: 190000 | C33: 0 | D33: 75000 | E33: 115000 | F33: 190000 | G33: 0 | H33: 75000 | I33: 115000
A34: Insta Tour Ciudad Amurallada Hotel | B34: 190000 | C34: 0 | D34: 75000 | E34: 115000 | F34: 190000 | G34: 0 | H34: 75000 | I34: 115000
A35: Isla Bela | B35: 360000 | C35: 310000 | D35: 120000 | E35: 240000 | F35: 400000 | G35: 310000 | H35: =F35-I35 -> 135000 | I35: 265000 | J35: OK Geni
A36: Isla Bela Criança | B36: 320000 | C36: 150000 | D36: 100000 | E36: 220000 | F36: 300000 | G36: 150000 | H36: =F36-I36 -> 60000 | I36: 240000 | J36: OK Geni
A37: Isla Del Encanto | B37: 370000 | C37: 250000 | D37: 138000 | E37: 232000 | F37: 370000 | G37: 250000 | H37: 138000 | I37: 232000
A38: Isla Del Encanto Criança até 10 anos | B38: 310000 | C38: 140000 | D38: 190000 | E38: 120000 | F38: 310000 | G38: 140000 | H38: 190000 | I38: 120000
A39: Isla Del Encanto Criança até 4 anos | B39: 270000 | C39: 90000 | D39: 170000 | E39: 100000 | F39: 270000 | G39: 90000 | H39: 170000 | I39: 100000
A40: Isla Del Encanto TA | E40: 200000 | I40: 200000
A41: Isla Del Pirata | B41: 330000 | C41: 200000 | D41: 170000 | E41: 160000 | F41: 330000 | G41: 200000 | H41: 170000 | I41: 160000
...
