Workbook

Sheet Precificação Simples Nacional
A1: Pedro Resende | C1: Código | D1: Descrição | E1: Preço custo (COP) | F1: Valor de venda (COP) | G1: Preço custo (BRL) | H1: IOF | I1: Valor após IOF | J1: Valor de IOF Bruto | K1: Cotação COP | L1: Spread | M1: Cotação Real | N1: Valor SPREAD BRUTO | O1: Custo Convertido (US) | P1: Preço de venda | Q1: Simples Nacional (%) | R1: Outros custos diretos (%) | S1: Comissão (R$) | T1: Margem bruta | U1: MARKUP | V1: MARKDOWN | W1: CLD
C2: Lancha-001 | D2: Veleiro 5 pessoas - Lancha | E2: =E45 -> 6395050 | F2: 10703326 | G2: =(E2*M2)*(1+H2) -> 9262.8202 | H2: 0.035 | I2: =G2*(1-H2) -> 8938.6215 | J2: =G2-I2 -> 324.19871 | K2: 0.00137 | L2: 0.0215 | M2: =K2*(1+L2) -> 0.001399455 | N2: =(I2*L2)+15 -> 207.18036 | O2: =(I2*M2)+L20 -> 12.530698 | P2: =(F2*M2)*(1+H2) -> 15503.081 | Q2: 0.06 | S2: =(P2-G2)*0.2 -> 1248.0522 | T2: =P2-(G2+S2)-(P2*R2) -> 4992.2088 | U2: =IFERROR((P2-G2)/G2,"") -> 0.6736891 | V2: =IFERROR((P2-G2)/P2,"") -> 0.40251747 | W2: =IFERROR(T2/P2,"") -> 0.32201398
C3: Lancha-003 | D3: Veleiro 5 pessoas - Regular | E3: 3670000 | G3: =(E3*M3)*(1+H3) -> 5315.7598 | H3: 0.035 | I3: =G3*(1-H3) -> 5129.7082 | J3: =G3-I3 -> 186.05159 | K3: 0.00137 | L3: 0.0215 | M3: =K3*(1+L3) -> 0.001399455 | N3: =(I3*L3)+15 -> 125.28873 | O3: =(I3*M3)+L21 -> 7.2002959 | P3: =G3*1.75 -> 9302.5797 | Q3: 0.06 | S3: =(P3-G3)*0.2 -> 797.36398 | T3: =P3-(G3+S3)-(P3*R3) -> 3189.4559 | U3: =IFERROR((P3-G3)/G3,"") -> 0.75 | V3: =IFERROR((P3-G3)/P3,"") -> 0.42857143 | W3: =IFERROR(T3/P3,"") -> 0.34285714
C4: DEBCAR-001 | D4: 8 pessoas - Debora Carvalho - Regular | E4: 12140000 | G4: =(E4*M4)*(1+H4) -> 17767.297 | H4: 0.035 | I4: =G4*(1-H4) -> 17145.441 | J4: =G4-I4 -> 621.85538 | K4: 0.00138428 | L4: 0.0215 | M4: =K4*(1+L4) -> 0.001414042 | N4: =(I4*L4)+15 -> 383.62699 | O4: =(I4*M4)+L27 -> 24.265874 | P4: =G4*1.5069 -> 26773.539 | Q4: 0.06 | S4: =(P4-G4)*0.2 -> 1801.2485 | T4: =P4-(G4+S4)-(P4*R4) -> 7204.9941 | U4: =IFERROR((P4-G4)/G4,"") -> 0.5069 | V4: =IFERROR((P4-G4)/P4,"") -> 0.33638596 | W4: =IFERROR(T4/P4,"") -> 0.26910877
C5: DEBCAR-003 | D5: 8 pessoas - Debora Carvalho - Lancha | E5: 12840000 | G5: =(E5*M5)*(1+H5) -> 18791.77 | H5: 0.035 | I5: =G5*(1-H5) -> 18134.058 | J5: =G5-I5 -> 657.71195 | K5: 0.00138428 | L5: 0.0215 | M5: =K5*(1+L5) -> 0.001414042 | N5: =(I5*L5)+15 -> 404.88225 | O5: =(I5*M5)+L33 -> 25.66382 | P5: =G5*1.51 -> 28375.573 | Q5: 0.06 | S5: =(P5-G5)*0.2 -> 1916.7605 | T5: =P5-(G5+S5)-(P5*R5) -> 7667.0422 | U5: =IFERROR((P5-G5)/G5,"") -> 0.51 | V5: =IFERROR((P5-G5)/P5,"") -> 0.33774834 | W5: =IFERROR(T5/P5,"") -> 0.27019868
C6: DEBCAR-005 | D6: 5 pessoas - Debora Carvalho - Lancha + Bogota | E6: 9457000 | G6: =(E6*M6)*(1+H6) -> 13697.859 | H6: 0.035 | I6: =G6*(1-H6) -> 13218.433 | J6: =G6-I6 -> 479.42505 | K6: 0.00137 | L6: 0.0215 | M6: =K6*(1+L6) -> 0.001399455 | N6: =(I6*L6)+15 -> 299.19632 | O6: =(I6*M6)+L34 -> 18.498603 | P6: =G6*1.4169 -> 19408.496 | Q6: 0.06 | S6: =(P6-G6)*0.2 -> 1142.1274 | T6: =P6-(G6+S6)-(P6*R6) -> 4568.5098 | U6: =IFERROR((P6-G6)/G6,"") -> 0.4169 | V6: =IFERROR((P6-G6)/P6,"") -> 0.29423389 | W6: =IFERROR(T6/P6,"") -> 0.23538711
C7: DEBCAR-006 | D7: 5 pessoas - Debora Carvalho - Lancha + Bogota | E7: 9457000 | G7: =(E7*M7)*(1+H7) -> 13697.859 | H7: 0.035 | I7: =G7*(1-H7) -> 13218.433 | J7: =G7-I7 -> 479.42505 | K7: 0.00137 | L7: 0.0215 | M7: =K7*(1+L7) -> 0.001399455 | N7: =(I7*L7)+15 -> 299.19632 | O7: =(I7*M7)+L34 -> 18.498603 | P7: =G7*1.4169 -> 19408.496 | Q7: 0.06 | S7: =(P7-G7)*0.2 -> 1142.1274 | T7: =P7-(G7+S7)-(P7*R7) -> 4568.5098 | U7: =IFERROR((P7-G7)/G7,"") -> 0.4169 | V7: =IFERROR((P7-G7)/P7,"") -> 0.29423389 | W7: =IFERROR(T7/P7,"") -> 0.23538711
C8: DEBCAR-007 | D8: 4 pessoas - Debora Carvalho - ctg + bog | E8: =E173 -> 7861600 | F8: =F173 -> 12232000 | G8: =(E8*M8)*(1+H8) -> 11505.715 | H8: 0.035 | I8: =G8*(1-H8) -> 11103.015 | J8: =G8-I8 -> 402.70002 | K8: 0.00137 | L8: 0.0215 | M8: =M4 -> 0.001414042 | N8: =(I8*L8)+15 -> 253.71482 | O8: =(I8*M8)+L35 -> 15.70013 | P8: 18096 | Q8: 0.06 | S8: =(P8-G8)*0.2 -> 1318.057 | T8: =P8-(G8+S8)-(P8*R8) -> 5272.2281 | U8: =IFERROR((P8-G8)/G8,"") -> 0.57278363 | V8: =IFERROR((P8-G8)/P8,"") -> 0.36418463 | W8: =IFERROR(T8/P8,"") -> 0.29134771
C9: DEBCAR-008 | D9: 4 pessoas - Debora Carvalho - ctg + bog | E9: =E187 -> 7648800 | F9: =F187 -> 11632000 | G9: =(E9*M9)*(1+H9) -> 11078.797 | H9: 0.035 | I9: =G9*(1-H9) -> 10691.039 | J9: =G9-I9 -> 387.75788 | K9: 0.00137 | L9: 0.0215 | M9: =K9*(1+L9) -> 0.001399455 | N9: =(I9*L9)+15 -> 244.85733 | O9: =(I9*M9)+L36 -> 14.961628 | P9: 17208 | Q9: 0.06 | S9: =(P9-G9)*0.2 -> 1225.8407 | T9: =P9-(G9+S9)-(P9*R9) -> 4903.3626 | U9: =IFERROR((P9-G9)/G9,"") -> 0.55323727 | V9: =IFERROR((P9-G9)/P9,"") -> 0.35618336 | W9: =IFERROR(T9/P9,"") -> 0.28494669
C10: CLULIV-001 | D10: 12 pessoas - Clube do Livro | E10: 8207280 | G10: =(E10*M10)*(1+H10) -> 12011.629 | H10: 0.035 | I10: =G10*(1-H10) -> 11591.222 | J10: =G10-I10 -> 420.40702 | K10: 0.00138428 | L10: 0.0215 | M10: =K10*(1+L10) -> 0.001414042 | N10: =(I10*L10)+15 -> 264.21128 | O10: =(I10*M10)+L37 -> 16.390475 | P10: =G10*1.7483 -> 20999.931 | Q10: 0.06 | S10: =(P10-G10)*0.2 -> 1797.6604 | T10: =P10-(G10+S10)-(P10*R10) -> 7190.6417 | U10: =IFERROR((P10-G10)/G10,"") -> 0.7483 | V10: =IFERROR((P10-G10)/P10,"") -> 0.42801579 | W10: =IFERROR(T10/P10,"") -> 0.34241263
C11: CLULIV-003 | D11: 12 pessoas - Clube do Livro - Sem Sibarita | E11: 6887280 | G11: =(E11*M11)*(1+H11) -> 10079.765 | H11: 0.035 | I11: =G11*(1-H11) -> 9726.9732 | J11: =G11-I11 -> 352.79177 | K11: 0.00138428 | L11: 0.0215 | M11: =K11*(1+L11) -> 0.001414042 | N11: =(I11*L11)+15 -> 224.12992 | O11: =(I11*M11)+L38 -> 13.754349 | P11: =G11*1.6827 -> 16961.22 | Q11: 0.06 | S11: =(P11-G11)*0.2 -> 1376.2911 | T11: =P11-(G11+S11)-(P11*R11) -> 5505.1644 | U11: =IFERROR((P11-G11)/G11,"") -> 0.6827 | V11: =IFERROR((P11-G11)/P11,"") -> 0.405717 | W11: =IFERROR(T11/P11,"") -> 0.3245736
C12: CLULIV-005 | D12: 12 pessoas - Clube do Livro - Sem Sibarita E LANCHA TOP | E12: 7612000 | G12: =(E12*M12)*(1+H12) -> 11025.494 | H12: 0.035 | I12: =G12*(1-H12) -> 10639.602 | J12: =G12-I12 -> 385.8923 | K12: 0.00137 | L12: 0.0215 | M12: =K12*(1+L12) -> 0.001399455 | N12: =(I12*L12)+15 -> 243.75144 | O12: =(I12*M12)+L39 -> 14.889644 | P12: =G12 -> 11025.494 | Q12: 0.06 | S12: =(P12-G12)*0.2 -> 0 | T12: =P12-(G12+S12)-(P12*R12) -> 0 | U12: =IFERROR((P12-G12)/G12,"") -> 0 | V12: =IFERROR((P12-G12)/P12,"") -> 0 | W12: =IFERROR(T12/P12,"") -> 0
C13: CLULIV-007 | D13: 12 pessoas - Clube do Livro - AZIMUT 55 | E13: 17332000 | G13: =(E13*M13)*(1+H13) -> 25104.291 | H13: 0.035 | I13: =G13*(1-H13) -> 24225.641 | J13: =G13-I13 -> 878.6502 | K13: 0.00137 | L13: 0.0215 | M13: =K13*(1+L13) -> 0.001399455 | N13: =(I13*L13)+15 -> 535.85129 | O13: =(I13*M13)+L40 -> 33.902695 | P13: =G13*1.4476 -> 36340.972 | Q13: 0.06 | S13: =(P13-G13)*0.2 -> 2247.3362 | T13: =P13-(G13+S13)-(P13*R13) -> 8989.3447 | U13: =IFERROR((P13-G13)/G13,"") -> 0.4476 | V13: =IFERROR((P13-G13)/P13,"") -> 0.30920144 | W13: =IFERROR(T13/P13,"") -> 0.24736115
C14: MURCRU-001 | D14: murilo cRUZ | E14: 4100000 | G14: =(E14*M14)*(1+H14) -> 6000.4873 | H14: 0.035 | I14: =G14*(1-H14) -> 5790.4703 | J14: =G14-I14 -> 210.01706 | K14: 0.00138428 | L14: 0.0215 | M14: =K14*(1+L14) -> 0.001414042 | N14: =(I14*L14)+15 -> 139.49511 | O14: =(I14*M14)+L41 -> 8.1879683 | P14: =G14*1.2929 -> 7758.03 | Q14: 0.06 | S14: =(P14-G14)*0.2 -> 351.50855 | T14: =P14-(G14+S14)-(P14*R14) -> 1406.0342 | U14: =IFERROR((P14-G14)/G14,"") -> 0.2929 | V14: =IFERROR((P14-G14)/P14,"") -> 0.22654498 | W14: =IFERROR(T14/P14,"") -> 0.18123598
C15: PATRIG-001 | D15: Patricia Rigotto - renovacao votos | E15: 10145000 | G15: =(E15*M15)*(1+H15) -> 14847.547 | H15: 0.035 | I15: =G15*(1-H15) -> 14327.883 | J15: =G15-I15 -> 519.66415 | K15: 0.00138428 | L15: 0.0215 | M15: =K15*(1+L15) -> 0.001414042 | N15: =(I15*L15)+15 -> 323.04949 | O15: =(I15*M15)+L42 -> 20.260229 | P15: =G15*1.27 -> 18856.385 | Q15: 0.06 | S15: =(P15-G15)*0.2 -> 801.76755 | T15: =P15-(G15+S15)-(P15*R15) -> 3207.0702 | U15: =IFERROR((P15-G15)/G15,"") -> 0.27 | V15: =IFERROR((P15-G15)/P15,"") -> 0.21259843 | W15: =IFERROR(T15/P15,"") -> 0.17007874
C16: SENODA-001 | D16: Senhor Odair | E16: 5624000 | F16: 9864 | G16: =F16*(1+H16) -> 10209.24 | H16: 0.035 | I16: =G16*(1-H16) -> 9851.9166 | J16: =G16-I16 -> 357.3234 | K16: 0.00138428 | L16: 0.0215 | M16: =K16*(1+L16) -> 0.001414042 | N16: =(I16*L16)+15 -> 226.81621 | O16: =(I16*M16)+L43 -> 13.931024 | P16: =G16*1.7539 -> 17905.986 | Q16: 0.06 | S16: =(P16-G16)*0.2 -> 1539.3492 | T16: =P16-(G16+S16)-(P16*R16) -> 6157.3968 | U16: =IFERROR((P16-G16)/G16,"") -> 0.7539 | V16: =IFERROR((P16-G16)/P16,"") -> 0.42984207 | W16: =IFERROR(T16/P16,"") -> 0.34387365
C17: ANETUR-001 | D17: Anetur | E17: 12212000 | G17: =(E17*M17)*(1+H17) -> 17872.671 | H17: 0.035 | I17: =G17*(1-H17) -> 17247.127 | J17: =G17-I17 -> 625.54348 | K17: 0.00138428 | L17: 0.0215 | M17: =K17*(1+L17) -> 0.001414042 | N17: =(I17*L17)+15 -> 385.81324 | O17: =(I17*M17)+L44 -> 24.388163 | P17: =G17*1.51 -> 26987.733 | Q17: 0.06 | S17: =(P17-G17)*0.2 -> 1823.0124 | T17: =P17-(G17+S17)-(P17*R17) -> 7292.0498 | U17: =IFERROR((P17-G17)/G17,"") -> 0.51 | V17: =IFERROR((P17-G17)/P17,"") -> 0.33774834 | W17: =IFERROR(T17/P17,"") -> 0.27019868
C18: AMAANT-001 | D18: Amanda Antunes | E18: 7671000 | F18: 12094000 | G18: =(E18*M18)*(1+H18) -> 11226.765 | H18: 0.035 | I18: =G18*(1-H18) -> 10833.829 | J18: =G18-I18 -> 392.93679 | K18: 0.00138428 | L18: 0.0215 | M18: =K18*(1+L18) -> 0.001414042 | N18: =(I18*L18)+15 -> 247.92732 | O18: =(I18*M18)+L45 -> 15.319489 | P18: 16991 | Q18: 0.06 | S18: =(P18-G18)*0.2 -> 1152.8469 | T18: =P18-(G18+S18)-(P18*R18) -> 4611.3877 | U18: =IFERROR((P18-G18)/G18,"") -> 0.51343681 | V18: =IFERROR((P18-G18)/P18,"") -> 0.33925223 | W18: =IFERROR(T18/P18,"") -> 0.27140178
C19: ANAPIM-001 | D19: Ana Pimentel | E19: 4790000 | F19: 6795000 | G19: =(E19*M19)*(1+H19) -> 7010.3254 | H19: 0.035 | I19: =G19*(1-H19) -> 6764.964 | J19: =G19-I19 -> 245.36139 | K19: 0.00138428 | L19: 0.0215 | M19: =K19*(1+L19) -> 0.001414042 | N19: =(I19*L19)+15 -> 160.44673 | O19: =(I19*M19)+L47 -> 9.5659434 | P19: =(F19*M19)*(1+H19) -> 9944.7101 | Q19: 0.06 | S19: =(P19-G19)*0.2 -> 586.87693 | T19: =P19-(G19+S19)-(P19*R19) -> 2347.5077 | U19: =IFERROR((P19-G19)/G19,"") -> 0.41858038 | V19: =IFERROR((P19-G19)/P19,"") -> 0.2950699 | W19: =IFERROR(T19/P19,"") -> 0.23605592
C20: FERMEN-001 | D20: Fer Mendes | E20: 350000 | F20: 26860000 | G20: =(E20*M20)*(1+H20) -> 512.23672 | H20: 0.035 | I20: =G20*(1-H20) -> 494.30844 | J20: =G20-I20 -> 17.928285 | K20: 0.00138428 | L20: 0.0215 | M20: =K20*(1+L20) -> 0.001414042 | N20: =(I20*L20)+15 -> 25.627631 | O20: =(I20*M20)+L48 -> 0.6989729 | P20: =(F20*M20)*(1+H20) -> 39310.51 | Q20: 0.06 | S20: =(P20-G20)*0.2 -> 7759.6546 | T20: =P20-(G20+S20)-(P20*R20) -> 31038.618 | U20: =IFERROR((P20-G20)/G20,"") -> 75.742857 | V20: =IFERROR((P20-G20)/P20,"") -> 0.98696947 | W20: =IFERROR(T20/P20,"") -> 0.78957558
C21: FABCAS-001 | D21: FABIANA CASTERO | E21: 844000 | F21: 1200000 | G21: =(E21*M21)*(1+H21) -> 1235.2223 | H21: 0.035 | I21: =G21*(1-H21) -> 1191.9895 | J21: =G21-I21 -> 43.232779 | K21: 0.00138428 | L21: 0.0215 | M21: =K21*(1+L21) -> 0.001414042 | N21: =(I21*L21)+15 -> 40.627774 | O21: =(I21*M21)+L49 -> 1.6855232 | P21: =(F21*M21)*(1+H21) -> 1756.2402 | Q21: 0.06 | S21: =(P21-G21)*0.2 -> 104.20358 | T21: =P21-(G21+S21)-(P21*R21) -> 416.81434 | U21: =IFERROR((P21-G21)/G21,"") -> 0.42180095 | V21: =IFERROR((P21-G21)/P21,"") -> 0.29666667 | W21: =IFERROR(T21/P21,"") -> 0.23733333
C22: analuciacardoso001 | D22: ana lucia black friday | E22: 490000 | F22: =F582 -> 650000 | G22: =(E22*M22)*(1+H22) -> 717.13141 | H22: 0.035 | I22: =G22*(1-H22) -> 692.03181 | J22: =G22-I22 -> 25.099599 | K22: 0.00138428 | L22: 0.0215 | M22: =K22*(1+L22) -> 0.001414042 | N22: =(I22*L22)+15 -> 29.878684 | O22: =(I22*M22)+L49 -> 0.97856206 | P22: =(F22*M22)*(1+H22) -> 951.29677 | Q22: 0.06 | S22: =(P22-G22)*0.2 -> 46.833072 | T22: =P22-(G22+S22)-(P22*R22) -> 187.33229 | U22: =IFERROR((P22-G22)/G22,"") -> 0.32653061 | V22: =IFERROR((P22-G22)/P22,"") -> 0.24615385 | W22: =IFERROR(T22/P22,"") -> 0.19692308
C23: DINARY | D23: Dinary | E23: =E563 -> 5650000 | F23: =F563 -> 7710000 | G23: =(E23*M23)*(1+H23) -> 8268.9642 | H23: 0.035 | I23: =G23*(1-H23) -> 7979.5505 | J23: =G23-I23 -> 289.41375 | K23: 0.00138428 | L23: 0.0215 | M23: =K23*(1+L23) -> 0.001414042 | N23: =(I23*L23)+15 -> 186.56034 | O23: =(I23*M23)+L50 -> 11.28342 | P23: =(F23*M23)*(1+H23) -> 11283.843 | Q23: 0.06 | S23: =(P23-G23)*0.2 -> 602.9758 | T23: =P23-(G23+S23)-(P23*R23) -> 2411.9032 | U23: =IFERROR((P23-G23)/G23,"") -> 0.36460177 | V23: =IFERROR((P23-G23)/P23,"") -> 0.26718547 | W23: =IFERROR(T23/P23,"") -> 0.21374838
C24: GIULIA001 | D24: Giulia Morais | E24: 3462000 | F24: 4910000 | G24: =(E24*M24)*(1+H24) -> 5066.7529 | H24: 0.035 | I24: =G24*(1-H24) -> 4889.4166 | J24: =G24-I24 -> 177.33635 | K24: 0.00138428 | L24: 0.0215 | M24: =K24*(1+L24) -> 0.001414042 | N24: =(I24*L24)+15 -> 120.12246 | O24: =(I24*M24)+L50 -> 6.9138405 | P24: =(F24*M24)*(1+H24) -> 7185.9494 | Q24: 0.06 | S24: =(P24-G24)*0.2 -> 423.8393 | T24: =P24-(G24+S24)-(P24*R24) -> 1695.3572 | U24: =IFERROR((P24-G24)/G24,"") -> 0.41825534 | V24: =IFERROR((P24-G24)/P24,"") -> 0.29490835 | W24: =IFERROR(T24/P24,"") -> 0.23592668
C25: cha revelacao | E25: 2230000 | F25: 3700000 | G25: =(E25*M25)*(1+H25) -> 0
C26: FERMEN-001 | E26: 15736000 | F26: 23760000 | G26: =(E26*M26)*(1+H26) -> 23030.163 | H26: 0.035 | I26: =G26*(1-H26) -> 22224.107 | J26: =G26-I26 -> 806.05571 | K26: 0.00138428 | L26: 0.0215 | M26: =K26*(1+L26) -> 0.001414042 | N26: =(I26*L26)+15 -> 492.81831 | O26: =(I26*M26)+L51 -> 31.425822 | P26: =G26*1.664 -> 38322.191 | Q26: 0.06 | S26: =(P26-G26)*0.2 -> 3058.4056 | T26: =P26-(G26+S26)-(P26*R26) -> 12233.623 | U26: =IFERROR((P26-G26)/G26,"") -> 0.664 | V26: =IFERROR((P26-G26)/P26,"") -> 0.39903846 | W26: =IFERROR(T26/P26,"") -> 0.31923077
C27: FERMEN-002 | E27: 142500 | G27: =(E27*M27)*(1+H27) -> 208.55352 | H27: 0.035 | I27: =G27*(1-H27) -> 201.25415 | J27: =G27-I27 -> 7.2993733 | K27: 0.00138428 | L27: 0.0215 | M27: =K27*(1+L27) -> 0.001414042 | N27: =(I27*L27)+15 -> 19.326964 | O27: =(I27*M27)+L52 -> 0.28458182 | P27: =G27*1.664 -> 347.03306 | Q27: 0.06 | S27: =(P27-G27)*0.2 -> 27.695908 | T27: =P27-(G27+S27)-(P27*R27) -> 110.78363 | U27: =IFERROR((P27-G27)/G27,"") -> 0.664 | V27: =IFERROR((P27-G27)/P27,"") -> 0.39903846 | W27: =IFERROR(T27/P27,"") -> 0.31923077
G28: =(E28*M28)*(1+H28) -> 0 | H28: 0.035 | I28: =G28*(1-H28) -> 0 | J28: =G28-I28 -> 0 | K28: 0.00138428 | L28: 0.0215 | M28: =K28*(1+L28) -> 0.001414042 | N28: =(I28*L28)+15 -> 15 | O28: =(I28*M28)+L53 -> 0 | P28: =G28*1.664 -> 0 | Q28: 0.06 | S28: =(P28-G28)*0.2 -> 0 | T28: =P28-(G28+S28)-(P28*R28) -> 0 | U28: =IFERROR((P28-G28)/G28,"") | V28: =IFERROR((P28-G28)/P28,"") | W28: =IFERROR(T28/P28,"")
P29: =G29*1.664 -> 0 | T29: =P29-(G29+S29)-(P29*R29) -> 0 | U29: =IFERROR((P29-G29)/G29,"") | V29: =IFERROR((P29-G29)/P29,"") | W29: =IFERROR(T29/P29,"")
C30: ana caludia | D30: 12 pax | E30: 180000 | F30: 300000 | G30: =(E30*M30)*(1+H30) -> 282.46657 | H30: 0.035 | I30: =G30*(1-H30) -> 272.58024 | J30: =G30-I30 -> 9.8863301 | K30: 0.00148428 | L30: 0.0215 | M30: =K30*(1+L30) -> 0.001516192 | N30: =(I30*L30)+15 -> 20.860475 | O30: =(I30*M30)+L50 -> 0.41328399 | P30: =G30*1.664 -> 470.02438 | Q30: 0.06 | S30: =(P30-G30)*0.2 -> 37.511561 | T30: =P30-(G30+S30)-(P30*R30) -> 150.04624 | U30: =IFERROR((P30-G30)/G30,"") -> 0.664 | V30: =IFERROR((P30-G30)/P30,"") -> 0.39903846 | W30: =IFERROR(T30/P30,"") -> 0.31923077
C31: brielly10 | D31: 12 pax | E31: =E792 -> 6600000 | F31: =F792 -> 9050000 | G31: =(E31*M31)*(1+H31) -> 9659.321 | H31: 0.035 | I31: =G31*(1-H31) -> 9321.2448 | J31: =G31-I31 -> 338.07624 | K31: 0.00138428 | L31: 0.0215 | M31: =K31*(1+L31) -> 0.001414042 | N31: =(I31*L31)+15 -> 215.40676 | O31: =(I31*M31)+L51 -> 13.180632 | P31: =G31*1.664 -> 16073.11 | Q31: 0.06 | S31: =(P31-G31)*0.2 -> 1282.7578 | T31: =P31-(G31+S31)-(P31*R31) -> 5131.0313 | U31: =IFERROR((P31-G31)/G31,"") -> 0.664 | V31: =IFERROR((P31-G31)/P31,"") -> 0.39903846 | W31: =IFERROR(T31/P31,"") -> 0.31923077
C32: alice | D32: Mínimo 15 e máximo 23 pagantes + 1 TC free | E32: 2928400 | F32: 3810000 | G32: =(E32*M32)*(1+H32) -> 4285.8115 | H32: 0.035 | I32: =G32*(1-H32) -> 4135.8081 | J32: =G32-I32 -> 150.0034 | K32: 0.00138428 | L32: 0.0215 | M32: =K32*(1+L32) -> 0.001414042 | N32: =(I32*L32)+15 -> 103.91987 | O32: =(I32*M32)+L52 -> 5.8482064 | P32: =G32*1.664 -> 7131.5903 | Q32: 0.06 | S32: =(P32-G32)*0.2 -> 569.15576 | T32: =P32-(G32+S32)-(P32*R32) -> 2276.6231 | U32: =IFERROR((P32-G32)/G32,"") -> 0.664 | V32: =IFERROR((P32-G32)/P32,"") -> 0.39903846 | W32: =IFERROR(T32/P32,"") -> 0.31923077
C33: giselerodrigues001 | D33: 2 pax | E33: =E618 -> 1648000 | F33: =F618 -> 2360000 | G33: =(E33*M33)*(1+H33) -> 2411.9032 | H33: 0.035 | I33: =G33*(1-H33) -> 2327.4866 | J33: =G33-I33 -> 84.416612 | K33: 0.00138428 | L33: 0.0215 | M33: =K33*(1+L33) -> 0.001414042 | N33: =(I33*L33)+15 -> 65.040961 | O33: =(I33*M33)+L53 -> 3.2911638 | P33: =G33*1.664 -> 4013.4069 | Q33: 0.06 | S33: =(P33-G33)*0.2 -> 320.30074 | T33: =P33-(G33+S33)-(P33*R33) -> 1281.203 | U33: =IFERROR((P33-G33)/G33,"") -> 0.664 | V33: =IFERROR((P33-G33)/P33,"") -> 0.39903846 | W33: =IFERROR(T33/P33,"") -> 0.31923077
T34: =P34-(G34+S34)-(P34*R34) -> 0 | U34: =IFERROR((P34-G34)/G34,"") | V34: =IFERROR((P34-G34)/P34,"") | W34: =IFERROR(T34/P34,"")
E35: Valor de Custo(COP) | F35: Valor de venda(COP) | G35: Markup | H35: comissao | T35: =P35-(G35+S35)-(P35*R35) -> #VALUE! | U35: =IFERROR((P35-G35)/G35,"") | V35: =IFERROR((P35-G35)/P35,"") | W35: =IFERROR(T35/P35,"")
C36: Veleiro 5 pessoas - Lancha | D36: Transfer in | E36: 170000 | F36: 350000 | G36: =F36/E36 -> 2.0588235 | T36: =P36-(G36+S36)-(P36*R36) -> -2.0588235 | U36: =IFERROR((P36-G36)/G36,"") -> -1 | V36: =IFERROR((P36-G36)/P36,"") | W36: =IFERROR(T36/P36,"")
D37: Guia | E37: 600000 | F37: =400000*5 -> 2000000 | G37: =F37/E37 -> 3.3333333 | T37: =P37-(G37+S37)-(P37*R37) -> -3.3333333 | U37: =IFERROR((P37-G37)/G37,"") -> -1 | V37: =IFERROR((P37-G37)/P37,"") | W37: =IFERROR(T37/P37,"")
D38: Castelo | E38: =36000*5 -> 180000 | G38: =F38/E38 -> 0 | T38: =P38-(G38+S38)-(P38*R38) -> 0 | U38: =IFERROR((P38-G38)/G38,"") | V38: =IFERROR((P38-G38)/P38,"") | W38: =IFERROR(T38/P38,"")
D39: Carro 4 horas | E39: 350000 | G39: =F39/E39 -> 0 | T39: =P39-(G39+S39)-(P39*R39) -> 0 | U39: =IFERROR((P39-G39)/G39,"") | V39: =IFERROR((P39-G39)/P39,"") | W39: =IFERROR(T39/P39,"")
D40: água | E40: 50000 | G40: =F40/E40 -> 0 | T40: =P40-(G40+S40)-(P40*R40) -> 0 | U40: =IFERROR((P40-G40)/G40,"") | V40: =IFERROR((P40-G40)/P40,"") | W40: =IFERROR(T40/P40,"")
...

Sheet Precificação por Produto
E2: Precificação | X2: Formatos de visualização | AA2: Pesquisa | AE2: Histórico de vendas
A3: DATA da Cotação | B3: Código | C3: Passeio | D3: Descrição | E3: Preço custo (COP) | F3: Valor de venda (COP) | G3: Quantidade de pessoas | H3: Preço custo (BRL) | I3: IOF | J3: Valor após IOF | K3: Valor de IOF Bruto | L3: Cotação COP | M3: Spread | N3: Cotação Real | O3: Valor SPREAD BRUTO | P3: Custo Convertido (US) | Q3: Preço de venda | R3: Simples Nacional (%) | S3: Outros custos diretos (%) | T3: ENTRADA | V3: Comissão Jadhe (R$) | W3: Margem bruta | X3: MARKUP | Y3: MARKDOWN | Z3: CLD | AA3: Pesquisa 1 | AB3: Pesquisa 2 | AC3: Pesquisa 3 | AD3: Estabelecimento | AE3: Custo 2025 | AF3: Mês 2 | AG3: Mês 3 | AH3: Média venda mensal | AI3: Vendas acumuladas
A4: Bogotá BOG PASS | T4: =F4-E4 -> 0
T5: =F5-E5 -> 0
A6: 2026 | C6: city tour imperdíveis - manhã | D6: Regular | E6: 119200 | F6: 300000 | G6: 1 | H6: =((E6*N6)*(1+I6))*G6 -> 176.05622 | I6: 0.035 | J6: =H6*(1-I6) -> 169.89426 | K6: =H6-J6 -> 6.1619678 | L6: 0.001397 | M6: 0.0215 | N6: =L6*(1+M6) -> 0.0014270355 | O6: =(J6*M6)+15 -> 18.652726 | P6: =(J6*N6)+M6 -> 0.26394513 | Q6: =((F6*N6)*(1+I6))*G6 -> 443.09452 | R6: 0.06 | T6: =F6-E6 -> 180800 | U6: =T6*(1-I6-M6) -> 170584.8 | V6: =(F6-E6)*0.2 -> 36160 | W6: =(F6*(1-I6-M6)-(E6+V6)-(F6*S6)-(F6*R6)) -> 109690 | X6: =IFERROR((F6-E6)/E6,"") -> 1.5167785 | Y6: =IFERROR((Q6-H6)/Q6,"") -> 0.60266667 | Z6: =IFERROR(W6/F6,"") -> 0.36563333
A7: 2026 | C7: city tour bairros inconicos - tarde | D7: Regular | E7: 119200 | F7: 300000 | G7: 1 | H7: =((E7*N7)*(1+I7))*G7 -> 176.05622 | I7: 0.035 | J7: =H7*(1-I7) -> 169.89426 | K7: =H7-J7 -> 6.1619678 | L7: 0.001397 | M7: 0.0215 | N7: =L7*(1+M7) -> 0.0014270355 | O7: =(J7*M7)+15 -> 18.652726 | P7: =(J7*N7)+M7 -> 0.26394513 | Q7: =((F7*N7)*(1+I7))*G7 -> 443.09452 | R7: 0.06 | T7: =F7-E7 -> 180800 | U7: =T7*(1-I7-M7) -> 170584.8 | V7: =(F7-E7)*0.2 -> 36160 | W7: =F7-(E7+V7)-(F7*S7)-(F7*R7) -> 126640 | X7: =IFERROR((F7-E7)/E7,"") -> 1.5167785 | Y7: =IFERROR((Q7-H7)/Q7,"") -> 0.60266667 | Z7: =IFERROR(W7/F7,"") -> 0.42213333
A8: 2026 | C8: Catedral de Sal (BOG PASS) | D8: Regular | E8: 263200 | F8: 380000 | G8: 1 | H8: =((E8*N8)*(1+I8))*G8 -> 388.74159 | I8: 0.035 | J8: =H8*(1-I8) -> 375.13564 | K8: =H8-J8 -> 13.605956 | L8: 0.001397 | M8: 0.0215 | N8: =L8*(1+M8) -> 0.0014270355 | O8: =(J8*M8)+15 -> 23.065416 | P8: =(J8*N8)+M8 -> 0.55683187 | Q8: =((F8*N8)*(1+I8))*G8 -> 561.25306 | R8: 0.06 | T8: =F8-E8 -> 116800 | U8: =T8*(1-I8-M8) -> 110200.8 | V8: =(F8-E8)*0.2 -> 23360 | W8: =F8-(E8+V8)-(F8*S8)-(F8*R8) -> 70640 | X8: =IFERROR((F8-E8)/E8,"") -> 0.443769 | Y8: =IFERROR((Q8-H8)/Q8,"") -> 0.30736842 | Z8: =IFERROR(W8/F8,"") -> 0.18589474
A9: 2026 | C9: Catedral de Sal + Guatavita (BOG PASS) | D9: Regular | E9: 343200 | F9: 600000 | G9: 1 | H9: =((E9*N9)*(1+I9))*G9 -> 506.90013 | I9: 0.035 | J9: =H9*(1-I9) -> 489.15863 | K9: =H9-J9 -> 17.741505 | L9: 0.001397 | M9: 0.0215 | N9: =L9*(1+M9) -> 0.0014270355 | O9: =(J9*M9)+15 -> 25.516911 | P9: =(J9*N9)+M9 -> 0.71954673 | Q9: =((F9*N9)*(1+I9))*G9 -> 886.18905 | R9: 0.06 | T9: =F9-E9 -> 256800 | U9: =T9*(1-I9-M9) -> 242290.8 | V9: =(F9-E9)*0.2 -> 51360 | W9: =F9-(E9+V9)-(F9*S9)-(F9*R9) -> 169440 | X9: =IFERROR((F9-E9)/E9,"") -> 0.74825175 | Y9: =IFERROR((Q9-H9)/Q9,"") -> 0.428 | Z9: =IFERROR(W9/F9,"") -> 0.2824
A10: 2026 | C10: Finca Cafeteira (Grupal) (BOG PASS) | D10: Regular | E10: 343200 | F10: 650000 | G10: 1 | H10: =((E10*N10)*(1+I10))*G10 -> 506.90013 | I10: 0.035 | J10: =H10*(1-I10) -> 489.15863 | K10: =H10-J10 -> 17.741505 | L10: 0.001397 | M10: 0.0215 | N10: =L10*(1+M10) -> 0.0014270355 | O10: =(J10*M10)+15 -> 25.516911 | P10: =(J10*N10)+M10 -> 0.71954673 | Q10: =((F10*N10)*(1+I10))*G10 -> 960.03813 | R10: 0.06 | T10: =F10-E10 -> 306800 | U10: =T10*(1-I10-M10) -> 289465.8 | V10: =(F10-E10)*0.2 -> 61360 | W10: =F10-(E10+V10)-(F10*S10)-(F10*R10) -> 206440 | X10: =IFERROR((F10-E10)/E10,"") -> 0.89393939 | Y10: =IFERROR((Q10-H10)/Q10,"") -> 0.472 | Z10: =IFERROR(W10/F10,"") -> 0.3176
A11: 2026 | C11: Transfer in - DIURNO - 06am -09pm (bog pass) | D11: Carro 3 Pessoas | E11: 112000 | F11: 360000 | G11: 1 | H11: =((E11*N11)*(1+I11))*G11 -> 165.42196 | I11: 0.035 | J11: =H11*(1-I11) -> 159.63219 | K11: =H11-J11 -> 5.7897684 | L11: 0.001397 | M11: 0.0215 | N11: =L11*(1+M11) -> 0.0014270355 | O11: =(J11*M11)+15 -> 18.432092 | P11: =(J11*N11)+M11 -> 0.2493008 | Q11: =((F11*N11)*(1+I11))*G11 -> 531.71343 | R11: 0.06 | T11: =F11-E11 -> 248000 | U11: =T11*(1-I11-M11) -> 233988 | V11: =(F11-E11)*0.2 -> 49600 | W11: =F11-(E11+V11)-(F11*S11)-(F11*R11) -> 176800 | X11: =IFERROR((F11-E11)/E11,"") -> 2.2142857 | Y11: =IFERROR((Q11-H11)/Q11,"") -> 0.68888889 | Z11: =IFERROR(W11/F11,"") -> 0.49111111
A12: 2026 | C12: Transfer in - DIURNO - 06am -09pm (bog pass) | D12: VAN 4-6 PAX | E12: 173600 | F12: 550000 | G12: 1 | H12: =((E12*N12)*(1+I12))*G12 -> 256.40403 | I12: 0.035 | J12: =H12*(1-I12) -> 247.42989 | K12: =H12-J12 -> 8.9741411 | L12: 0.001397 | M12: 0.0215 | N12: =L12*(1+M12) -> 0.0014270355 | O12: =(J12*M12)+15 -> 20.319743 | P12: =(J12*N12)+M12 -> 0.37459124 | Q12: =((F12*N12)*(1+I12))*G12 -> 812.33996 | R12: 0.06 | T12: =F12-E12 -> 376400 | U12: =T12*(1-I12-M12) -> 355133.4 | V12: =(F12-E12)*0.2 -> 75280 | W12: =F12-(E12+V12)-(F12*S12)-(F12*R12) -> 268120 | X12: =IFERROR((F12-E12)/E12,"") -> 2.1682028 | Y12: =IFERROR((Q12-H12)/Q12,"") -> 0.68436364 | Z12: =IFERROR(W12/F12,"") -> 0.48749091
A13: 2026 | C13: Transfer in - DIURNO - 06am - 09pm (bog pass) | D13: VAN 7-10 Pax | E13: 260800 | F13: 770000 | G13: 1 | H13: =((E13*N13)*(1+I13))*G13 -> 385.19684 | I13: 0.035 | J13: =H13*(1-I13) -> 371.71495 | K13: =H13-J13 -> 13.481889 | L13: 0.001397 | M13: 0.0215 | N13: =L13*(1+M13) -> 0.0014270355 | O13: =(J13*M13)+15 -> 22.991871 | P13: =(J13*N13)+M13 -> 0.55195043 | Q13: =((F13*N13)*(1+I13))*G13 -> 1137.2759 | R13: 0.06 | T13: =F13-E13 -> 509200 | U13: =T13*(1-I13-M13) -> 480430.2 | V13: =(F13-E13)*0.2 -> 101840 | W13: =F13-(E13+V13)-(F13*S13)-(F13*R13) -> 361160 | X13: =IFERROR((F13-E13)/E13,"") -> 1.952454 | Y13: =IFERROR((Q13-H13)/Q13,"") -> 0.6612987 | Z13: =IFERROR(W13/F13,"") -> 0.46903896
A14: 2026 | C14: Transfer in - NOTURNO - 06am - 09pm (bog pass) | D14: Carro 3 Pessoas | E14: 127200 | F14: 360000 | G14: 1 | H14: =((E14*N14)*(1+I14))*G14 -> 187.87208 | I14: 0.035 | J14: =H14*(1-I14) -> 181.29655 | K14: =H14-J14 -> 6.5755227 | L14: 0.001397 | M14: 0.0215 | N14: =L14*(1+M14) -> 0.0014270355 | O14: =(J14*M14)+15 -> 18.897876 | P14: =(J14*N14)+M14 -> 0.28021662 | Q14: =((F14*N14)*(1+I14))*G14 -> 531.71343 | R14: 0.06 | T14: =F14-E14 -> 232800 | U14: =T14*(1-I14-M14) -> 219646.8 | V14: =(F14-E14)*0.2 -> 46560 | W14: =F14-(E14+V14)-(F14*S14)-(F14*R14) -> 164640 | X14: =IFERROR((F14-E14)/E14,"") -> 1.8301887 | Y14: =IFERROR((Q14-H14)/Q14,"") -> 0.64666667 | Z14: =IFERROR(W14/F14,"") -> 0.45733333
A15: 2026 | C15: Transfer in - NOTURNIO - 06am - 09pm (bog pass) | D15: VAN 4-6 PAX | E15: 216800 | F15: 550000 | G15: 1 | H15: =((E15*N15)*(1+I15))*G15 -> 320.20964 | I15: 0.035 | J15: =H15*(1-I15) -> 309.0023 | K15: =H15-J15 -> 11.207337 | L15: 0.001397 | M15: 0.0215 | N15: =L15*(1+M15) -> 0.0014270355 | O15: =(J15*M15)+15 -> 21.64355 | P15: =(J15*N15)+M15 -> 0.46245726 | Q15: =((F15*N15)*(1+I15))*G15 -> 812.33996 | R15: 0.06 | T15: =F15-E15 -> 333200 | U15: =T15*(1-I15-M15) -> 314374.2 | V15: =(F15-E15)*0.2 -> 66640 | W15: =F15-(E15+V15)-(F15*S15)-(F15*R15) -> 233560 | X15: =IFERROR((F15-E15)/E15,"") -> 1.5369004 | Y15: =IFERROR((Q15-H15)/Q15,"") -> 0.60581818 | Z15: =IFERROR(W15/F15,"") -> 0.42465455
A16: 2026 | C16: Transfer in - NOTURNO - 06am - 09pm (bog pass) | D16: VAN 7-10 Pax | E16: 292000 | F16: 770000 | G16: 1 | H16: =((E16*N16)*(1+I16))*G16 -> 431.27867 | I16: 0.035 | J16: =H16*(1-I16) -> 416.18392 | K16: =H16-J16 -> 15.094753 | L16: 0.001397 | M16: 0.0215 | N16: =L16*(1+M16) -> 0.0014270355 | O16: =(J16*M16)+15 -> 23.947954 | P16: =(J16*N16)+M16 -> 0.61540922 | Q16: =((F16*N16)*(1+I16))*G16 -> 1137.2759 | R16: 0.06 | T16: =F16-E16 -> 478000 | U16: =T16*(1-I16-M16) -> 450993 | V16: =(F16-E16)*0.2 -> 95600 | W16: =F16-(E16+V16)-(F16*S16)-(F16*R16) -> 336200 | X16: =IFERROR((F16-E16)/E16,"") -> 1.6369863 | Y16: =IFERROR((Q16-H16)/Q16,"") -> 0.62077922 | Z16: =IFERROR(W16/F16,"") -> 0.43662338
A17: 2026 | C17: Transfer OUT - DIURNO - 06am -09pm (bog pass) | D17: Carro 3 Pessoas | E17: 80000 | F17: 360000 | G17: 1 | H17: =((E17*N17)*(1+I17))*G17 -> 118.15854 | I17: 0.035 | J17: =H17*(1-I17) -> 114.02299 | K17: =H17-J17 -> 4.1355489 | L17: 0.001397 | M17: 0.0215 | N17: =L17*(1+M17) -> 0.0014270355 | O17: =(J17*M17)+15 -> 17.451494 | P17: =(J17*N17)+M17 -> 0.18421486 | Q17: =((F17*N17)*(1+I17))*G17 -> 531.71343 | R17: 0.06 | T17: =F17-E17 -> 280000 | U17: =T17*(1-I17-M17) -> 264180 | V17: =(F17-E17)*0.2 -> 56000 | W17: =F17-(E17+V17)-(F17*S17)-(F17*R17) -> 202400 | X17: =IFERROR((F17-E17)/E17,"") -> 3.5 | Y17: =IFERROR((Q17-H17)/Q17,"") -> 0.77777778 | Z17: =IFERROR(W17/F17,"") -> 0.56222222
A18: 2026 | C18: Transfer OUT - DIURNO - 06am -09pm (bog pass) | D18: VAN 4-6 PAX | E18: 140000 | F18: 550000 | G18: 1 | H18: =((E18*N18)*(1+I18))*G18 -> 206.77744 | I18: 0.035 | J18: =H18*(1-I18) -> 199.54023 | K18: =H18-J18 -> 7.2372105 | L18: 0.001397 | M18: 0.0215 | N18: =L18*(1+M18) -> 0.0014270355 | O18: =(J18*M18)+15 -> 19.290115 | P18: =(J18*N18)+M18 -> 0.306251 | Q18: =((F18*N18)*(1+I18))*G18 -> 812.33996 | R18: 0.06 | T18: =F18-E18 -> 410000 | U18: =T18*(1-I18-M18) -> 386835 | V18: =(F18-E18)*0.2 -> 82000 | W18: =F18-(E18+V18)-(F18*S18)-(F18*R18) -> 295000 | X18: =IFERROR((F18-E18)/E18,"") -> 2.9285714 | Y18: =IFERROR((Q18-H18)/Q18,"") -> 0.74545455 | Z18: =IFERROR(W18/F18,"") -> 0.53636364
... A22: 2026 | C22: Transfer OUT - NOTURNO - 06am - 09pm (bog pass) | D22: VAN 7-10 Pax | E22: 244000 | F22: 770000 | G22: 1 | H22: =((E22*N22)*(1+I22))*G22 -> 360.38355 | I22: 0.035 | J22: =H22*(1-I22) -> 347.77012 | K22: =H22-J22 -> 12.613424 | L22: 0.001397 | M22: 0.0215 | N22: =L22*(1+M22) -> 0.0014270355 | O22: =(J22*M22)+15 -> 22.477058 | P22: =(J22*N22)+M22 -> 0.51778031 | Q22: =((F22*N22)*(1+I22))*G22 -> 1137.2759 | R22: 0.06 | T22: =F22-E22 -> 526000 | U22: =T22*(1-I22-M22) -> 496281 | V22: =(F22-E22)*0.2 -> 105200 | W22: =F22-(E22+V22)-(F22*S22)-(F22*R22) -> 374600 | X22: =IFERROR((F22-E22)/E22,"") -> 2.1557377 | Y22: =IFERROR((Q22-H22)/Q22,"") -> 0.68311688 | Z22: =IFERROR(W22/F22,"") -> 0.48649351
T23: =F23-E23 -> 0 | U23: =T23*(1-I23-M23) -> 0 | V23: =(F23-E23)*0.2 -> 0 | W23: =F23-(E23+V23)-(F23*S23)-(F23*R23) -> 0 | X23: =IFERROR((F23-E23)/E23,"") | Z23: =IFERROR(W23/F23,"")
A24: Cartagena | T24: =F24-E24 -> 0 | U24: =T24*(1-I24-M24) -> 0 | V24: =(F24-E24)*0.2 -> 0 | W24: =F24-(E24+V24)-(F24*S24)-(F24*R24) -> 0 | X24: =IFERROR((F24-E24)/E24,"") | Z24: =IFERROR(W24/F24,"")
A25: 2026 | C25: Jantar Fenix Beach | E25: 225000 | F25: 370000 | G25: 1 | H25: =((E25*N25)*(1+I25))*G25 -> 332.32089 | I25: 0.035 | J25: =H25*(1-I25) -> 320.68966 | K25: =H25-J25 -> 11.631231 | L25: 0.001397 | M25: 0.0215 | N25: =L25*(1+M25) -> 0.0014270355 | O25: =(J25*M25)+15 -> 21.894828 | P25: =(J25*N25)+M25 -> 0.47913553 | Q25: =((F25*N25)*(1+I25))*G25 -> 546.48324 | R25: 0.06 | T25: =F25-E25 -> 145000 | U25: =T25*(1-I25-M25) -> 136807.5 | V25: =(F25-E25)*0.2 -> 29000 | W25: =F25-(E25+V25)-(F25*S25)-(F25*R25) -> 93800 | X25: =IFERROR((F25-E25)/E25,"") -> 0.64444444 | Y25: =IFERROR((Q25-H25)/Q25,"") -> 0.39189189 | Z25: =IFERROR(W25/F25,"") -> 0.25351351 | AH25: =IFERROR(AVERAGE(AE25:AG25),"") | AI25: =AE25+AF25+AG25 -> 0
A26: 2026 | C26: Jantar Fenix Beach | E26: 150000 | F26: 300000 | G26: 1 | H26: =((E26*N26)*(1+I26))*G26 -> 221.54726 | I26: 0.035 | J26: =H26*(1-I26) -> 213.79311 | K26: =H26-J26 -> 7.7541541 | L26: 0.001397 | M26: 0.0215 | N26: =L26*(1+M26) -> 0.0014270355 | O26: =(J26*M26)+15 -> 19.596552 | P26: =(J26*N26)+M26 -> 0.32659035 | Q26: =((F26*N26)*(1+I26))*G26 -> 443.09452 | R26: 0.06 | T26: =F26-E26 -> 150000 | U26: =T26*(1-I26-M26) -> 141525 | V26: =(F26-E26)*0.2 -> 30000 | W26: =F26-(E26+V26)-(F26*S26)-(F26*R26) -> 102000 | X26: =IFERROR((F26-E26)/E26,"") -> 1 | Y26: =IFERROR((Q26-H26)/Q26,"") -> 0.5 | Z26: =IFERROR(W26/F26,"") -> 0.34 | AH26: =IFERROR(AVERAGE(AE26:AG26),"") | AI26: =AE26+AF26+AG26 -> 0
H27: =((E27*N27)*(1+I27))*G27 -> 0 | Q27: =((F27*N27)*(1+I27))*G27 -> 0 | R27: 0.06 | T27: =F27-E27 -> 0 | U27: =T27*(1-I27-M27) -> 0 | V27: =(F27-E27)*0.2 -> 0 | W27: =F27-(E27+V27)-(F27*S27)-(F27*R27) -> 0 | X27: =IFERROR((F27-E27)/E27,"") | Z27: =IFERROR(W27/F27,"")
A28: 2026 | C28: Corona Island | E28: 633000 | F28: 850000 | G28: 1 | H28: =((E28*N28)*(1+I28))*G28 -> 934.92944 | I28: 0.035 | J28: =H28*(1-I28) -> 902.20691 | K28: =H28-J28 -> 32.722531 | L28: 0.001397 | M28: 0.0215 | N28: =L28*(1+M28) -> 0.0014270355 | O28: =(J28*M28)+15 -> 34.397449 | P28: =(J28*N28)+M28 -> 1.3089813 | Q28: =((F28*N28)*(1+I28))*G28 -> 1255.4345 | R28: 0.06 | T28: =F28-E28 -> 217000 | U28: =T28*(1-I28-M28) -> 204739.5 | V28: =(F28-E28)*0.2 -> 43400 | W28: =F28-(E28+V28)-(F28*S28)-(F28*R28) -> 122600 | X28: =IFERROR((F28-E28)/E28,"") -> 0.34281201 | Y28: =IFERROR((Q28-H28)/Q28,"") -> 0.25529412 | Z28: =IFERROR(W28/F28,"") -> 0.14423529 | AH28: =IFERROR(AVERAGE(AE28:AG28),"") | AI28: =AE28+AF28+AG28 -> 0
T29: =F29-E29 -> 0 | U29: =T29*(1-I29-M29) -> 0 | V29: =(F29-E29)*0.2 -> 0 | W29: =F29-(E29+V29)-(F29*S29)-(F29*R29) -> 0 | X29: =IFERROR((F29-E29)/E29,"") | Z29: =IFERROR(W29/F29,"")
A30: 2026 | C30: Capri Premium | E30: 390000 | F30: 610000 | G30: 1 | H30: =((E30*N30)*(1+I30))*G30 -> 576.02288 | I30: 0.035 | J30: =H30*(1-I30) -> 555.86208 | K30: =H30-J30 -> 20.160801 | L30: 0.001397 | M30: 0.0215 | N30: =L30*(1+M30) -> 0.0014270355 | O30: =(J30*M30)+15 -> 26.951035 | P30: =(J30*N30)+M30 -> 0.81473492 | Q30: =((F30*N30)*(1+I30))*G30 -> 900.95886 | R30: 0.06 | T30: =F30-E30 -> 220000 | U30: =T30*(1-I30-M30) -> 207570 | V30: =(F30-E30)*0.2 -> 44000 | W30: =F30-(E30+V30)-(F30*S30)-(F30*R30) -> 139400 | X30: =IFERROR((F30-E30)/E30,"") -> 0.56410256 | Y30: =IFERROR((Q30-H30)/Q30,"") -> 0.36065574 | Z30: =IFERROR(W30/F30,"") -> 0.22852459 | AH30: =IFERROR(AVERAGE(AE30:AG30),"") | AI30: =AE30+AF30+AG30 -> 0
A31: 2026 | C31: Capri Classic | E31: 330000 | F31: 510000 | G31: 1 | H31: =((E31*N31)*(1+I31))*G31 -> 487.40398 | I31: 0.035 | J31: =H31*(1-I31) -> 470.34484 | K31: =H31-J31 -> 17.059139 | L31: 0.001397 | M31: 0.0215 | N31: =L31*(1+M31) -> 0.0014270355 | O31: =(J31*M31)+15 -> 25.112414 | P31: =(J31*N31)+M31 -> 0.69269878 | Q31: =((F31*N31)*(1+I31))*G31 -> 753.26069 | R31: 0.06 | T31: =F31-E31 -> 180000 | U31: =T31*(1-I31-M31) -> 169830 | V31: =(F31-E31)*0.2 -> 36000 | W31: =F31-(E31+V31)-(F31*S31)-(F31*R31) -> 113400 | X31: =IFERROR((F31-E31)/E31,"") -> 0.54545455 | Y31: =IFERROR((Q31-H31)/Q31,"") -> 0.35294118 | Z31: =IFERROR(W31/F31,"") -> 0.22235294 | AH31: =IFERROR(AVERAGE(AE31:AG31),"") | AI31: =AE31+AF31+AG31 -> 0
T32: =F32-E32 -> 0 | U32: =T32*(1-I32-M32) -> 0 | V32: =(F32-E32)*0.2 -> 0 | W32: =F32-(E32+V32)-(F32*S32)-(F32*R32) -> 0 | X32: =IFERROR((F32-E32)/E32,"") | Z32: =IFERROR(W32/F32,"")
A33: 2026 | C33: Isla Bela | E33: 300000 | F33: 490000 | G33: 1 | H33: =((E33*N33)*(1+I33))*G33 -> 443.09452 | I33: 0.035 | J33: =H33*(1-I33) -> 427.58621 | K33: =H33-J33 -> 15.508308 | L33: 0.001397 | M33: 0.0215 | N33: =L33*(1+M33) -> 0.0014270355 | O33: =(J33*M33)+15 -> 24.193104 | P33: =(J33*N33)+M33 -> 0.63168071 | Q33: =((F33*N33)*(1+I33))*G33 -> 723.72105 | R33: 0.06 | T33: =F33-E33 -> 190000 | U33: =T33*(1-I33-M33) -> 179265 | V33: =(F33-E33)*0.2 -> 38000 | W33: =F33-(E33+V33)-(F33*S33)-(F33*R33) -> 122600 | X33: =IFERROR((F33-E33)/E33,"") -> 0.63333333 | Y33: =IFERROR((Q33-H33)/Q33,"") -> 0.3877551 | Z33: =IFERROR(W33/F33,"") -> 0.25020408 | AH33: =IFERROR(AVERAGE(AE33:AG33),"") | AI33: =AE33+AF33+AG33 -> 0
A34: 2026 | C34: Isla Bela chd - 03 a 10 anos | E34: 260000 | F34: 390000 | G34: 1 | H34: =((E34*N34)*(1+I34))*G34 -> 384.01525 | I34: 0.035 | J34: =H34*(1-I34) -> 370.57472 | K34: =H34-J34 -> 13.440534 | L34: 0.001397 | M34: 0.0215 | N34: =L34*(1+M34) -> 0.0014270355 | O34: =(J34*M34)+15 -> 22.967356 | P34: =(J34*N34)+M34 -> 0.55032328 | Q34: =((F34*N34)*(1+I34))*G34 -> 576.02288 | R34: 0.06 | T34: =F34-E34 -> 130000 | U34: =T34*(1-I34-M34) -> 122655 | V34: =(F34-E34)*0.2 -> 26000 | W34: =F34-(E34+V34)-(F34*S34)-(F34*R34) -> 80600 | X34: =IFERROR((F34-E34)/E34,"") -> 0.5 | Y34: =IFERROR((Q34-H34)/Q34,"") -> 0.33333333 | Z34: =IFERROR(W34/F34,"") -> 0.20666667 | AH34: =IFERROR(AVERAGE(AE34:AG34),"") | AI34: =AE34+AF34+AG34 -> 0
T35: =F35-E35 -> 0 | U35: =T35*(1-I35-M35) -> 0 | V35: =(F35-E35)*0.2 -> 0 | W35: =F35-(E35+V35)-(F35*S35)-(F35*R35) -> 0 | X35: =IFERROR((F35-E35)/E35,"") | Z35: =IFERROR(W35/F35,"")
A36: 2026 | C36: Mergulho iniciante | E36: 620000 | F36: 890000 | G36: 1 | H36: =((E36*N36)*(1+I36))*G36 -> 915.72868 | I36: 0.035 | J36: =H36*(1-I36) -> 883.67818 | K36: =H36-J36 -> 32.050504 | L36: 0.001397 | M36: 0.0215 | N36: =L36*(1+M36) -> 0.0014270355 | O36: =(J36*M36)+15 -> 33.999081 | P36: =(J36*N36)+M36 -> 1.2825401 | Q36: =((F36*N36)*(1+I36))*G36 -> 1314.5138 | R36: 0.06 | T36: =F36-E36 -> 270000 | U36: =T36*(1-I36-M36) -> 254745 | V36: =(F36-E36)*0.2 -> 54000 | W36: =F36-(E36+V36)-(F36*S36)-(F36*R36) -> 162600 | X36: =IFERROR((F36-E36)/E36,"") -> 0.43548387 | Y36: =IFERROR((Q36-H36)/Q36,"") -> 0.30337079 | Z36: =IFERROR(W36/F36,"") -> 0.18269663 | AH36: =IFERROR(AVERAGE(AE36:AG36),"") | AI36: =AE36+AF36+AG36 -> 0
A37: 2026 | C37: Mergulho para certificados | E37: 570000 | F37: 800000 | G37: 1 | H37: =((E37*N37)*(1+I37))*G37 -> 841.87959 | I37: 0.035 | J37: =H37*(1-I37) -> 812.41381 | K37: =H37-J37 -> 29.465786 | L37: 0.001397 | M37: 0.0215 | N37: =L37*(1+M37) -> 0.0014270355 | O37: =(J37*M37)+15 -> 32.466897 | P37: =(J37*N37)+M37 -> 1.1808433 | Q37: =((F37*N37)*(1+I37))*G37 -> 1181.5854 | R37: 0.06 | T37: =F37-E37 -> 230000 | U37: =T37*(1-I37-M37) -> 217005 | V37: =(F37-E37)*0.2 -> 46000 | W37: =F37-(E37+V37)-(F37*S37)-(F37*R37) -> 136000 | X37: =IFERROR((F37-E37)/E37,"") -> 0.40350877 | Y37: =IFERROR((Q37-H37)/Q37,"") -> 0.2875 | Z37: =IFERROR(W37/F37,"") -> 0.17 | AH37: =IFERROR(AVERAGE(AE37:AG37),"") | AI37: =AE37+AF37+AG37 -> 0
T38: =F38-E38 -> 0 | U38: =T38*(1-I38-M38) -> 0 | V38: =(F38-E38)*0.2 -> 0 | W38: =F38-(E38+V38)-(F38*S38)-(F38*R38) -> 0 | X38: =IFERROR((F38-E38)/E38,"") | Z38: =IFERROR(W38/F38,"")
A39: 2026 | C39: Bona Vida Sunset Adulto | E39: 134000 | F39: 230000 | G39: 1 | H39: =((E39*N39)*(1+I39))*G39 -> 197.91555 | I39: 0.035 | J39: =H39*(1-I39) -> 190.98851 | K39: =H39-J39 -> 6.9270444 | L39: 0.001397 | M39: 0.0215 | N39: =L39*(1+M39) -> 0.0014270355 | O39: =(J39*M39)+15 -> 19.106253 | P39: =(J39*N39)+M39 -> 0.29404738 | Q39: =((F39*N39)*(1+I39))*G39 -> 339.7058 | R39: 0.06 | T39: =F39-E39 -> 96000 | U39: =T39*(1-I39-M39) -> 90576 | V39: =(F39-E39)*0.2 -> 19200 | W39: =F39-(E39+V39)-(F39*S39)-(F39*R39) -> 63000 | X39: =IFERROR((F39-E39)/E39,"") -> 0.71641791 | Y39: =IFERROR((Q39-H39)/Q39,"") -> 0.4173913 | Z39: =IFERROR(W39/F39,"") -> 0.27391304 | AH39: =IFERROR(AVERAGE(AE39:AG39),"") | AI39: =AE39+AF39+AG39 -> 0
A40: 2026 | C40: Bona Vida Sunset CHD - 7 a 14 anos | E40: 67000 | F40: 190000 | G40: 1 | H40: =((E40*N40)*(1+I40))*G40 -> 98.957777 | I40: 0.035 | J40: =H40*(1-I40) -> 95.494255 | K40: =H40-J40 -> 3.4635222 | L40: 0.001397 | M40: 0.0215 | N40: =L40*(1+M40) -> 0.0014270355 | O40: =(J40*M40)+15 -> 17.053126 | P40: =(J40*N40)+M40 -> 0.15777369 | Q40: =((F40*N40)*(1+I40))*G40 -> 280.62653 | R40: 0.06 | T40: =F40-E40 -> 123000 | U40: =T40*(1-I40-M40) -> 116050.5 | V40: =(F40-E40)*0.2 -> 24600 | W40: =F40-(E40+V40)-(F40*S40)-(F40*R40) -> 87000 | X40: =IFERROR((F40-E40)/E40,"") -> 1.8358209 | Y40: =IFERROR((Q40-H40)/Q40,"") -> 0.64736842 | Z40: =IFERROR(W40/F40,"") -> 0.45789474 | AH40: =IFERROR(AVERAGE(AE40:AG40),"") | AI40: =AE40+AF40+AG40 -> 0
T41: =F41-E41 -> 0 | U41: =T41*(1-I41-M41) -> 0 | V41: =(F41-E41)*0.2 -> 0 | W41: =F41-(E41+V41)-(F41*S41)-(F41*R41) -> 0 | X41: =IFERROR((F41-E41)/E41,"") | Z41: =IFERROR(W41/F41,"")
A42: 2026 | C42: Bona Vida Islas Adulto | E42: 390000 | F42: 510000 | G42: 1 | H42: =((E42*N42)*(1+I42))*G42 -> 576.02288 | I42: 0.035 | J42: =H42*(1-I42) -> 555.86208 | K42: =H42-J42 -> 20.160801 | L42: 0.001397 | M42: 0.0215 | N42: =L42*(1+M42) -> 0.0014270355 | O42: =(J42*M42)+15 -> 26.951035 | P42: =(J42*N42)+M42 -> 0.81473492 | Q42: =((F42*N42)*(1+I42))*G42 -> 753.26069 | R42: 0.06 | T42: =F42-E42 -> 120000 | U42: =T42*(1-I42-M42) -> 113220 | V42: =(F42-E42)*0.2 -> 24000 | W42: =F42-(E42+V42)-(F42*S42)-(F42*R42) -> 65400 | X42: =IFERROR((F42-E42)/E42,"") -> 0.30769231 | Y42: =IFERROR((Q42-H42)/Q42,"") -> 0.23529412 | Z42: =IFERROR(W42/F42,"") -> 0.12823529 | AH42: =IFERROR(AVERAGE(AE42:AG42),"") | AI42: =AE42+AF42+AG42 -> 0
A43: 2026 | C43: Bona Vida Islas CHD - 7 a 14 anos | E43: 67000 | F43: 190000 | G43: 1 | H43: =((E43*N43)*(1+I43))*G43 -> 98.957777 | I43: 0.035 | J43: =H43*(1-I43) -> 95.494255 | K43: =H43-J43 -> 3.4635222 | L43: 0.001397 | M43: 0.0215 | N43: =L43*(1+M43) -> 0.0014270355 | O43: =(J43*M43)+15 -> 17.053126 | P43: =(J43*N43)+M43 -> 0.15777369 | Q43: =((F43*N43)*(1+I43))*G43 -> 280.62653 | R43: 0.06 | T43: =F43-E43 -> 123000 | U43: =T43*(1-I43-M43) -> 116050.5 | V43: =(F43-E43)*0.2 -> 24600 | W43: =F43-(E43+V43)-(F43*S43)-(F43*R43) -> 87000 | X43: =IFERROR((F43-E43)/E43,"") -> 1.8358209 | Y43: =IFERROR((Q43-H43)/Q43,"") -> 0.64736842 | Z43: =IFERROR(W43/F43,"") -> 0.45789474 | AH43: =IFERROR(AVERAGE(AE43:AG43),"") | AI43: =AE43+AF43+AG43 -> 0
T44: =F44-E44 -> 0 | U44: =T44*(1-I44-M44) -> 0 | V44: =(F44-E44)*0.2 -> 0 | W44: =F44-(E44+V44)-(F44*S44)-(F44*R44) -> 0 | X44: =IFERROR((F44-E44)/E44,"") | Z44: =IFERROR(W44/F44,"")
...

Sheet Saldos e Devoluções Ju
A2: inte | D2: DEZEMBRO | E2: STATUS | F2: CONSULTORA | G2: camnbio dia venda | H2: camnbio dia pgto
A3: Data | B3: Nombre | C3: Passeio | D3: Valor Total em Pesos Colombianos TOTAL | E3: Pagamento
A4: 45266 | B4: Silvana Rigolino | C4: Walking Tour + Casti VIP 14:00 2PAX | D4: 310000 | E4: PAGO | F4: Jadhe/ Ju paga Saldo/ Pax Pagou por pix
A5: 45267 | B5: Silvana Rigolino | C5: PAO PAO (Con oceanario) 2 pax | D5: 420000 | E5: PAGO | F5: Jadhe/ Ju paga Saldo/ Pax Pagou por pix
A6: 45269 | B6: Tatiane Moura | C6: Welcome Tour 2 PAX 14:00 | D6: 265000 | E6: PAGO | F6: Jadhe/ Ju paga Saldo/ Pax Pagou por pix
A7: 45270 | B7: Tatiane Moura | C7: Mangata 2 pax | D7: 540000 | E7: PAGO | F7: Jadhe/ Ju paga Saldo/ Pax Pagou por pix
A8: 45275 | B8: Isabela Portilho | C8: Walking Tour + Casti VIP 14:00 2PAX | D8: 310000 | E8: PAGO | F8: Alessandra/ Ju paga Saldo /Pax pagou por pix
A9: 45278 | B9: Amanda Nobrega | C9: Walking Tour + Castillo Andres 09:00 2 PAX | D9: 50000 | E9: PAGO | F9: Alessandra/ Só pago da diferença do saldo total
A10: 45282 | B10: João Neto | C10: Walking Tour + Casti VIP 14:00 8PAX | D10: 600000 | E10: PAGO | F10: Jadhe/ Ju paga Saldo/ Pax Pagou por pix
A11: 45283 | B11: Marcela Nogueira | C11: Paue 2 pax | D11: 540000 | E11: PAGO | F11: Alessandra/ Ju paga Saldo /Pax pagou por pix
A12: 45287 | C12: Tour Escala 5 pax | D12: 850000 | E12: PAGO | F12: Agencia/ Ju paga saldo
A13: 45287 | B13: Karla Bueno | C13: SABAI 10 pax adultos, 6 adult y 4 CHILD | D13: 2850000 | E13: PAGO | F13: SI HIZO EL PAGO 2850 Y ERA 2560 - SALDO 290
A14: 45289 | B14: Anne Mello | C14: Bora Bora VIP 2 pax | D14: 40000 | E14: PAGO | F14: Jadhe/ Ju paga Saldo/ Pax Pagou por link
A15: 45294 | B15: Anita Varela | C15: Parada 4 asoleadoras | D15: 400000 | E15: PAGO | F15: Jadhe/ Ju paga Saldo/ Pax Pagou por pix
A16: 12/24/2023 | B16: Sandra Domenico | C16: Islabela 3 pax | D16: 60000 | E16: PAGO | F16: Jadhe/ Só pago da diferença do saldo total
A17: 12/28/2023 | B17: Diandra Ribas | C17: Walking Tour + Cast 1PAX - Andrés | D17: 155000 | E17: PAGO | F17: Jadhe/ Ju paga Saldo/ Pax Pagou por pix
A18: 12/29/2023 | B18: Daniela Fiori | C18: Walking Tour + Castillo San Felipe Andres 2024 | D18: 620000 | E18: PAGO | F18: Jadhe/ Ju paga Saldo/ Pax Pagou por pix
A19: 12/29/2023 | B19: Jaqueline Ornellas | C19: Walking Tour + Castillo Andres 09:00 2 PAX | D19: 50000 | E19: PAGO | F19: Alessandra/ Só pago da diferença do saldo total
A20: 12/30/2023 | B20: Carmen Meneses | C20: Walking Tour + Cast 6 PAX - Andrés | D20: 520000 | E20: PAGO | F20: Jadhe/ Ju paga Saldo/ Pax Pagou por pix
A21: 12/31/2023 | B21: Carmen Meneses | C21: Aviario 6 PAX - Andrés | D21: 340000 | E21: PAGO | F21: Jadhe/ Ju paga Saldo/ Pax Pagou por pix
A22: 12/31/2023 | B22: Julia Castanheira | C22: Sabai 2 pax | D22: 660000- 290.000= 370.000 | E22: PAGO | F22: Alessandra/ Ju paga Saldo /Pax pagou por pix
A31: SALDOS PENDENTES JU | D31: JANEIRO | E31: STATUS | F31: CONSULTORA
A32: Data | B32: Nombre | C32: Passeio | D32: Valor Total em Pesos Colombianos TOTAL | E32: Pagamento
A33: 45297 | B33: Ana Tunher | C33: Walking Tour + Castillo San Felipe VIP 14:00 3PAX 2024 | D33: 355.000COP | E33: PAGO | F33: Jadhe/ Ju paga Saldo/ Pax Pagou por pix
A34: 45298 | B34: Iara Malan | C34: Walking Tour + Cast 3PAX - Hernán | D34: 400000 | E34: PAGO | F34: Jadhe/ Ju paga Saldo/ Pax Pagou por pix
A35: 45301 | B35: Camila Recoliano | C35: Walking Tour + Castillo San Felipe Andres 09:00 2PAX 2024 | D35: 310000 | E35: PAGO | F35: Jadhe/ Ju paga Saldo/ Pax Pagou por pix
A36: 45302 | B36: Regina Sartore | C36: Walking Tour + Castillo San Felipe VIP 09:00 2PAX 2024 | D36: 310000 | E36: PAGO | F36: Jadhe/ Ju paga Saldo/ Pax Pagou por pix
A37: 45303 | B37: Priscilla Bezerra | C37: Isla del sol 2 pax | D37: 544000 | E37: PAGO | F37: Alessandra/ Ju paga Saldo /Pax pagou por pix
A38: 45303 | B38: Marcos Ribeiro | C38: Walking + Cast 2 PAX 14:00hrs- Andrés | D38: 310000 | E38: PAGO | F38: Jadhe/ Ju paga Saldo/ Pax Pagou por pix
A39: 45444 | B39: Carmen Meneses | C39: Boats 4 u | D39: 4347000 | E39: PAGO | F39: Jadhe/ Ju pagou 15% e incluimos transfers nos demais dias
A40: 01/18/2024 | B40: Ivanda Marques | C40: Mangata 4 pax | D40: 1160000 | E40: PAGO | F40: Alessandra/ Ju paga Saldo /Pax pagou por pix
A41: 45444 | B41: Carmen Meneses | C41: Parada Paue | D41: 600000 | E41: PAGO | F41: Jadhe/ Ju paga Saldo/ Pax Pagou por pix
A42: 45383 | B42: Guilherme Schasiepen | C42: Walking Tour + Castillo San Felipe 09:00 7PAX 2024 | D42: 580000 | E42: PAGO | F42: Jadhe/ Ju paga Saldo/ Pax Pagou por pix
A43: 45303 | B43: Gabriel de Souza | C43: Fenix jantar 2 pax | D43: 400000 | E43: PAGO | F43: Alessandra/ Ju paga Saldo /Pax pagou por pix
A44: 45352 | B44: Silvana Brito | C44: Walking Tour + Castillo San Felipe Andres 09:00 2 PAX | D44: 310000 | E44: PAGO | F44: Jadhe/ Ju paga Saldo/ Pax Pagou por pix
A45: 45413 | B45: Juliana Custodio | C45: Walking Tour + Castillo San Felipe Andres 14:00 2 PAX | D45: 310000 | E45: PAGO | F45: Alessandra/ Ju paga Saldo /Pax pagou por pix
A46: 45444 | B46: Ana Tunher | C46: Walking Tour + Castillo San Felipe VIP 14:00 3PAX 2024 | D46: 355000 | E46: PAGO | F46: Jadhe/ Ju paga Saldo/ Pax Pagou por pix
A47: 45303 | B47: Gabriel de Souza | C47: Bora vip 2 pax | D47: 660000 | E47: PAGO | F47: Alessandra/ Ju paga Saldo /Pax pagou por pix
A48: 45304 | B48: Gustavo Mestriner | C48: Walking Tour + Castillo San Felipe Andres 14:00 4 PAX 2024 | D48: 485000 | E48: PAGO | F48: Jadhe/ Ju paga Saldo/ Pax Pagou por pix
A49: 45304 | B49: Gabriel de Souza | C49: Isla Palma 2 pax | D49: 700000 | E49: PAGO | F49: Alessandra/ Ju paga Saldo /Pax pagou por pix
...

Sheet Grupo Bora
A1: GRUPO BORA BORA
A4: Bora Bora BC
B5: 45748 | C5: 45925 | D5: 2026 | E5: 46023
A6: Precio venta | B6: 390000 | C6: 430000 | D6: 450000 | E6: 450000
A7: Saldo | B7: 280000 | C7: =B7 -> 280000 | D7: =C7 -> 280000 | E7: 290000
A8: Comision | B8: =B6-B7 -> 110000 | C8: =C6-C7 -> 150000 | D8: =D6-D7 -> 170000 | E8: =E6-E7 -> 160000
A10: Bora Bora VIP
B11: 45748 | C11: 2026 | D11: 45925 | E11: 46023
A12: Precio venta | B12: 490000 | C12: 510000 | D12: 510000 | E12: 550000
A13: Saldo | B13: 370000 | C13: =B13 -> 370000 | D13: =B13 -> 370000 | E13: 380000
A14: Comision | B14: =B12-B13 -> 120000 | C14: =C12-C13 -> 140000 | D14: =D12-D13 -> 140000 | E14: =E12-E13 -> 170000
A16: Pao Pao
B17: 45748 | C17: 45925 | D17: 2026 | E17: 46023
A18: Precio venta | B18: 390000 | C18: 430000 | D18: 450000 | E18: 450000
A19: Saldo | B19: 270000 | C19: =B19 -> 270000 | D19: =C19 -> 270000 | E19: 280000
A20: Comision | B20: =B18-B19 -> 120000 | C20: =C18-C19 -> 160000 | D20: =D18-D21 -> 450000 | E20: =E18-E19 -> 170000
A22: Top 3 Ilhas
B23: 45748 | C23: 45925 | D23: 2026
A24: Precio venta | B24: 440000 | C24: 430000 | D24: 450000 | E24: 500000
A25: Saldo | B25: 330000 | C25: =B25 -> 330000 | D25: =C25 -> 330000 | E25: 360000
A26: Comision | B26: =B24-B25 -> 110000 | C26: =C24-C25 -> 100000 | D26: =D24-D25 -> 120000 | E26: =E24-E25 -> 140000

Sheet Cópia de Precificação por Produ
E2: Precificação | X2: Formatos de visualização | AA2: Pesquisa | AE2: Histórico de vendas
A3: DATA da Cotação | B3: Código | C3: Passeio | D3: Descrição | E3: Preço custo (COP) | F3: Valor de venda (COP) | G3: Quantidade de pessoas | H3: Preço custo (BRL) | I3: IOF | J3: Valor após IOF | K3: Valor de IOF Bruto | L3: Cotação COP | M3: Spread | N3: Cotação Real | O3: Valor SPREAD BRUTO | P3: Custo Convertido (US) | Q3: Preço de venda | R3: Simples Nacional (%) | S3: Outros custos diretos (%) | T3: ENTRADA | V3: Comissão Jadhe (R$) | W3: Margem bruta | X3: MARKUP | Y3: MARKDOWN | Z3: CLD | AA3: Pesquisa 1 | AB3: Pesquisa 2 | AC3: Pesquisa 3 | AD3: Estabelecimento | AE3: Custo 2025 | AF3: Mês 2 | AG3: Mês 3 | AH3: Média venda mensal | AI3: Vendas acumuladas
A4: Bogotá BOG PASS | T4: =F4-E4 -> 0
T5: =F5-E5 -> 0
A6: 2026 | C6: city tour imperdíveis - manhã | D6: Regular | E6: 119200 | F6: 300000 | G6: 1 | H6: =((E6*N6)*(1+I6))*G6 -> 176.05622 | I6: 0.035 | J6: =H6*(1-I6) -> 169.89426 | K6: =H6-J6 -> 6.1619678 | L6: 0.001397 | M6: 0.0215 | N6: =L6*(1+M6) -> 0.0014270355 | O6: =(J6*M6)+15 -> 18.652726 | P6: =(J6*N6)+M6 -> 0.26394513 | Q6: =((F6*N6)*(1+I6))*G6 -> 443.09452 | R6: 0.06 | T6: =F6-E6 -> 180800 | U6: =T6*(1-I6-M6) -> 170584.8 | V6: =(F6-E6)*0.2 -> 36160 | W6: =(F6*(1-I6-M6)-(E6+V6)-(F6*S6)-(F6*R6)) -> 109690 | X6: =IFERROR((F6-E6)/E6,"") -> 1.5167785 | Y6: =IFERROR((Q6-H6)/Q6,"") -> 0.60266667 | Z6: =IFERROR(W6/F6,"") -> 0.36563333
A7: 2026 | C7: city tour bairros inconicos - tarde | D7: Regular | E7: 119200 | F7: 300000 | G7: 1 | H7: =((E7*N7)*(1+I7))*G7 -> 176.05622 | I7: 0.035 | J7: =H7*(1-I7) -> 169.89426 | K7: =H7-J7 -> 6.1619678 | L7: 0.001397 | M7: 0.0215 | N7: =L7*(1+M7) -> 0.0014270355 | O7: =(J7*M7)+15 -> 18.652726 | P7: =(J7*N7)+M7 -> 0.26394513 | Q7: =((F7*N7)*(1+I7))*G7 -> 443.09452 | R7: 0.06 | T7: =F7-E7 -> 180800 | U7: =T7*(1-I7-M7) -> 170584.8 | V7: =(F7-E7)*0.2 -> 36160 | W7: =F7-(E7+V7)-(F7*S7)-(F7*R7) -> 126640 | X7: =IFERROR((F7-E7)/E7,"") -> 1.5167785 | Y7: =IFERROR((Q7-H7)/Q7,"") -> 0.60266667 | Z7: =IFERROR(W7/F7,"") -> 0.42213333
A8: 2026 | C8: Catedral de Sal (BOG PASS) | D8: Regular | E8: 263200 | F8: 380000 | G8: 1 | H8: =((E8*N8)*(1+I8))*G8 -> 388.74159 | I8: 0.035 | J8: =H8*(1-I8) -> 375.13564 | K8: =H8-J8 -> 13.605956 | L8: 0.001397 | M8: 0.0215 | N8: =L8*(1+M8) -> 0.0014270355 | O8: =(J8*M8)+15 -> 23.065416 | P8: =(J8*N8)+M8 -> 0.55683187 | Q8: =((F8*N8)*(1+I8))*G8 -> 561.25306 | R8: 0.06 | T8: =F8-E8 -> 116800 | U8: =T8*(1-I8-M8) -> 110200.8 | V8: =(F8-E8)*0.2 -> 23360 | W8: =F8-(E8+V8)-(F8*S8)-(F8*R8) -> 70640 | X8: =IFERROR((F8-E8)/E8,"") -> 0.443769 | Y8: =IFERROR((Q8-H8)/Q8,"") -> 0.30736842 | Z8: =IFERROR(W8/F8,"") -> 0.18589474
A9: 2026 | C9: Catedral de Sal + Guatavita (BOG PASS) | D9: Regular | E9: 343200 | F9: 600000 | G9: 1 | H9: =((E9*N9)*(1+I9))*G9 -> 506.90013 | I9: 0.035 | J9: =H9*(1-I9) -> 489.15863 | K9: =H9-J9 -> 17.741505 | L9: 0.001397 | M9: 0.0215 | N9: =L9*(1+M9) -> 0.0014270355 | O9: =(J9*M9)+15 -> 25.516911 | P9: =(J9*N9)+M9 -> 0.71954673 | Q9: =((F9*N9)*(1+I9))*G9 -> 886.18905 | R9: 0.06 | T9: =F9-E9 -> 256800 | U9: =T9*(1-I9-M9) -> 242290.8 | V9: =(F9-E9)*0.2 -> 51360 | W9: =F9-(E9+V9)-(F9*S9)-(F9*R9) -> 169440 | X9: =IFERROR((F9-E9)/E9,"") -> 0.74825175 | Y9: =IFERROR((Q9-H9)/Q9,"") -> 0.428 | Z9: =IFERROR(W9/F9,"") -> 0.2824
A10: 2026 | C10: Finca Cafeteira (Grupal) (BOG PASS) | D10: Regular | E10: 343200 | F10: 650000 | G10: 1 | H10: =((E10*N10)*(1+I10))*G10 -> 506.90013 | I10: 0.035 | J10: =H10*(1-I10) -> 489.15863 | K10: =H10-J10 -> 17.741505 | L10: 0.001397 | M10: 0.0215 | N10: =L10*(1+M10) -> 0.0014270355 | O10: =(J10*M10)+15 -> 25.516911 | P10: =(J10*N10)+M10 -> 0.71954673 | Q10: =((F10*N10)*(1+I10))*G10 -> 960.03813 | R10: 0.06 | T10: =F10-E10 -> 306800 | U10: =T10*(1-I10-M10) -> 289465.8 | V10: =(F10-E10)*0.2 -> 61360 | W10: =F10-(E10+V10)-(F10*S10)-(F10*R10) -> 206440 | X10: =IFERROR((F10-E10)/E10,"") -> 0.89393939 | Y10: =IFERROR((Q10-H10)/Q10,"") -> 0.472 | Z10: =IFERROR(W10/F10,"") -> 0.3176
A11: 2026 | C11: Transfer in - DIURNO - 06am -09pm (bog pass) | D11: Carro 3 Pessoas | E11: 112000 | F11: 360000 | G11: 1 | H11: =((E11*N11)*(1+I11))*G11 -> 165.42196 | I11: 0.035 | J11: =H11*(1-I11) -> 159.63219 | K11: =H11-J11 -> 5.7897684 | L11: 0.001397 | M11: 0.0215 | N11: =L11*(1+M11) -> 0.0014270355 | O11: =(J11*M11)+15 -> 18.432092 | P11: =(J11*N11)+M11 -> 0.2493008 | Q11: =((F11*N11)*(1+I11))*G11 -> 531.71343 | R11: 0.06 | T11: =F11-E11 -> 248000 | U11: =T11*(1-I11-M11) -> 233988 | V11: =(F11-E11)*0.2 -> 49600 | W11: =F11-(E11+V11)-(F11*S11)-(F11*R11) -> 176800 | X11: =IFERROR((F11-E11)/E11,"") -> 2.2142857 | Y11: =IFERROR((Q11-H11)/Q11,"") -> 0.68888889 | Z11: =IFERROR(W11/F11,"") -> 0.49111111
A12: 2026 | C12: Transfer in - DIURNO - 06am -09pm (bog pass) | D12: VAN 4-6 PAX | E12: 173600 | F12: 550000 | G12: 1 | H12: =((E12*N12)*(1+I12))*G12 -> 256.40403 | I12: 0.035 | J12: =H12*(1-I12) -> 247.42989 | K12: =H12-J12 -> 8.9741411 | L12: 0.001397 | M12: 0.0215 | N12: =L12*(1+M12) -> 0.0014270355 | O12: =(J12*M12)+15 -> 20.319743 | P12: =(J12*N12)+M12 -> 0.37459124 | Q12: =((F12*N12)*(1+I12))*G12 -> 812.33996 | R12: 0.06 | T12: =F12-E12 -> 376400 | U12: =T12*(1-I12-M12) -> 355133.4 | V12: =(F12-E12)*0.2 -> 75280 | W12: =F12-(E12+V12)-(F12*S12)-(F12*R12) -> 268120 | X12: =IFERROR((F12-E12)/E12,"") -> 2.1682028 | Y12: =IFERROR((Q12-H12)/Q12,"") -> 0.68436364 | Z12: =IFERROR(W12/F12,"") -> 0.48749091
A13: 2026 | C13: Transfer in - DIURNO - 06am - 09pm (bog pass) | D13: VAN 7-10 Pax | E13: 260800 | F13: 770000 | G13: 1 | H13: =((E13*N13)*(1+I13))*G13 -> 385.19684 | I13: 0.035 | J13: =H13*(1-I13) -> 371.71495 | K13: =H13-J13 -> 13.481889 | L13: 0.001397 | M13: 0.0215 | N13: =L13*(1+M13) -> 0.0014270355 | O13: =(J13*M13)+15 -> 22.991871 | P13: =(J13*N13)+M13 -> 0.55195043 | Q13: =((F13*N13)*(1+I13))*G13 -> 1137.2759 | R13: 0.06 | T13: =F13-E13 -> 509200 | U13: =T13*(1-I13-M13) -> 480430.2 | V13: =(F13-E13)*0.2 -> 101840 | W13: =F13-(E13+V13)-(F13*S13)-(F13*R13) -> 361160 | X13: =IFERROR((F13-E13)/E13,"") -> 1.952454 | Y13: =IFERROR((Q13-H13)/Q13,"") -> 0.6612987 | Z13: =IFERROR(W13/F13,"") -> 0.46903896
A14: 2026 | C14: Transfer in - NOTURNO - 06am - 09pm (bog pass) | D14: Carro 3 Pessoas | E14: 127200 | F14: 360000 | G14: 1 | H14: =((E14*N14)*(1+I14))*G14 -> 187.87208 | I14: 0.035 | J14: =H14*(1-I14) -> 181.29655 | K14: =H14-J14 -> 6.5755227 | L14: 0.001397 | M14: 0.0215 | N14: =L14*(1+M14) -> 0.0014270355 | O14: =(J14*M14)+15 -> 18.897876 | P14: =(J14*N14)+M14 -> 0.28021662 | Q14: =((F14*N14)*(1+I14))*G14 -> 531.71343 | R14: 0.06 | T14: =F14-E14 -> 232800 | U14: =T14*(1-I14-M14) -> 219646.8 | V14: =(F14-E14)*0.2 -> 46560 | W14: =F14-(E14+V14)-(F14*S14)-(F14*R14) -> 164640 | X14: =IFERROR((F14-E14)/E14,"") -> 1.8301887 | Y14: =IFERROR((Q14-H14)/Q14,"") -> 0.64666667 | Z14: =IFERROR(W14/F14,"") -> 0.45733333
A15: 2026 | C15: Transfer in - NOTURNIO - 06am - 09pm (bog pass) | D15: VAN 4-6 PAX | E15: 216800 | F15: 550000 | G15: 1 | H15: =((E15*N15)*(1+I15))*G15 -> 320.20964 | I15: 0.035 | J15: =H15*(1-I15) -> 309.0023 | K15: =H15-J15 -> 11.207337 | L15: 0.001397 | M15: 0.0215 | N15: =L15*(1+M15) -> 0.0014270355 | O15: =(J15*M15)+15 -> 21.64355 | P15: =(J15*N15)+M15 -> 0.46245726 | Q15: =((F15*N15)*(1+I15))*G15 -> 812.33996 | R15: 0.06 | T15: =F15-E15 -> 333200 | U15: =T15*(1-I15-M15) -> 314374.2 | V15: =(F15-E15)*0.2 -> 66640 | W15: =F15-(E15+V15)-(F15*S15)-(F15*R15) -> 233560 | X15: =IFERROR((F15-E15)/E15,"") -> 1.5369004 | Y15: =IFERROR((Q15-H15)/Q15,"") -> 0.60581818 | Z15: =IFERROR(W15/F15,"") -> 0.42465455
A16: 2026 | C16: Transfer in - NOTURNO - 06am - 09pm (bog pass) | D16: VAN 7-10 Pax | E16: 292000 | F16: 770000 | G16: 1 | H16: =((E16*N16)*(1+I16))*G16 -> 431.27867 | I16: 0.035 | J16: =H16*(1-I16) -> 416.18392 | K16: =H16-J16 -> 15.094753 | L16: 0.001397 | M16: 0.0215 | N16: =L16*(1+M16) -> 0.0014270355 | O16: =(J16*M16)+15 -> 23.947954 | P16: =(J16*N16)+M16 -> 0.61540922 | Q16: =((F16*N16)*(1+I16))*G16 -> 1137.2759 | R16: 0.06 | T16: =F16-E16 -> 478000 | U16: =T16*(1-I16-M16) -> 450993 | V16: =(F16-E16)*0.2 -> 95600 | W16: =F16-(E16+V16)-(F16*S16)-(F16*R16) -> 336200 | X16: =IFERROR((F16-E16)/E16,"") -> 1.6369863 | Y16: =IFERROR((Q16-H16)/Q16,"") -> 0.62077922 | Z16: =IFERROR(W16/F16,"") -> 0.43662338
A17: 2026 | C17: Transfer OUT - DIURNO - 06am -09pm (bog pass) | D17: Carro 3 Pessoas | E17: 80000 | F17: 360000 | G17: 1 | H17: =((E17*N17)*(1+I17))*G17 -> 118.15854 | I17: 0.035 | J17: =H17*(1-I17) -> 114.02299 | K17: =H17-J17 -> 4.1355489 | L17: 0.001397 | M17: 0.0215 | N17: =L17*(1+M17) -> 0.0014270355 | O17: =(J17*M17)+15 -> 17.451494 | P17: =(J17*N17)+M17 -> 0.18421486 | Q17: =((F17*N17)*(1+I17))*G17 -> 531.71343 | R17: 0.06 | T17: =F17-E17 -> 280000 | U17: =T17*(1-I17-M17) -> 264180 | V17: =(F17-E17)*0.2 -> 56000 | W17: =F17-(E17+V17)-(F17*S17)-(F17*R17) -> 202400 | X17: =IFERROR((F17-E17)/E17,"") -> 3.5 | Y17: =IFERROR((Q17-H17)/Q17,"") -> 0.77777778 | Z17: =IFERROR(W17/F17,"") -> 0.56222222
A18: 2026 | C18: Transfer OUT - DIURNO - 06am -09pm (bog pass) | D18: VAN 4-6 PAX | E18: 140000 | F18: 550000 | G18: 1 | H18: =((E18*N18)*(1+I18))*G18 -> 206.77744 | I18: 0.035 | J18: =H18*(1-I18) -> 199.54023 | K18: =H18-J18 -> 7.2372105 | L18: 0.001397 | M18: 0.0215 | N18: =L18*(1+M18) -> 0.0014270355 | O18: =(J18*M18)+15 -> 19.290115 | P18: =(J18*N18)+M18 -> 0.306251 | Q18: =((F18*N18)*(1+I18))*G18 -> 812.33996 | R18: 0.06 | T18: =F18-E18 -> 410000 | U18: =T18*(1-I18-M18) -> 386835 | V18: =(F18-E18)*0.2 -> 82000 | W18: =F18-(E18+V18)-(F18*S18)-(F18*R18) -> 295000 | X18: =IFERROR((F18-E18)/E18,"") -> 2.9285714 | Y18: =IFERROR((Q18-H18)/Q18,"") -> 0.74545455 | Z18: =IFERROR(W18/F18,"") -> 0.53636364
... A22: 2026 | C22: Transfer OUT - NOTURNO - 06am - 09pm (bog pass) | D22: VAN 7-10 Pax | E22: 244000 | F22: 770000 | G22: 1 | H22: =((E22*N22)*(1+I22))*G22 -> 360.38355 | I22: 0.035 | J22: =H22*(1-I22) -> 347.77012 | K22: =H22-J22 -> 12.613424 | L22: 0.001397 | M22: 0.0215 | N22: =L22*(1+M22) -> 0.0014270355 | O22: =(J22*M22)+15 -> 22.477058 | P22: =(J22*N22)+M22 -> 0.51778031 | Q22: =((F22*N22)*(1+I22))*G22 -> 1137.2759 | R22: 0.06 | T22: =F22-E22 -> 526000 | U22: =T22*(1-I22-M22) -> 496281 | V22: =(F22-E22)*0.2 -> 105200 | W22: =F22-(E22+V22)-(F22*S22)-(F22*R22) -> 374600 | X22: =IFERROR((F22-E22)/E22,"") -> 2.1557377 | Y22: =IFERROR((Q22-H22)/Q22,"") -> 0.68311688 | Z22: =IFERROR(W22/F22,"") -> 0.48649351
T23: =F23-E23 -> 0 | U23: =T23*(1-I23-M23) -> 0 | V23: =(F23-E23)*0.2 -> 0 | W23: =F23-(E23+V23)-(F23*S23)-(F23*R23) -> 0 | X23: =IFERROR((F23-E23)/E23,"") | Z23: =IFERROR(W23/F23,"")
A24: Cartagena | T24: =F24-E24 -> 0 | U24: =T24*(1-I24-M24) -> 0 | V24: =(F24-E24)*0.2 -> 0 | W24: =F24-(E24+V24)-(F24*S24)-(F24*R24) -> 0 | X24: =IFERROR((F24-E24)/E24,"") | Z24: =IFERROR(W24/F24,"")
A25: 2026 | C25: Jantar Fenix Beach | E25: 225000 | F25: 370000 | G25: 1 | H25: =((E25*N25)*(1+I25))*G25 -> 332.32089 | I25: 0.035 | J25: =H25*(1-I25) -> 320.68966 | K25: =H25-J25 -> 11.631231 | L25: 0.001397 | M25: 0.0215 | N25: =L25*(1+M25) -> 0.0014270355 | O25: =(J25*M25)+15 -> 21.894828 | P25: =(J25*N25)+M25 -> 0.47913553 | Q25: =((F25*N25)*(1+I25))*G25 -> 546.48324 | R25: 0.06 | T25: =F25-E25 -> 145000 | U25: =T25*(1-I25-M25) -> 136807.5 | V25: =(F25-E25)*0.2 -> 29000 | W25: =F25-(E25+V25)-(F25*S25)-(F25*R25) -> 93800 | X25: =IFERROR((F25-E25)/E25,"") -> 0.64444444 | Y25: =IFERROR((Q25-H25)/Q25,"") -> 0.39189189 | Z25: =IFERROR(W25/F25,"") -> 0.25351351 | AH25: =IFERROR(AVERAGE(AE25:AG25),"") | AI25: =AE25+AF25+AG25 -> 0
